<mujoco model="stretch">
  <compiler angle="radian" assetdir="assets"/>

  <!-- <option integrator="implicitfast" impratio="10" cone="elliptic" noslip_iterations="3">
    <flag multiccd="enable"/>
  </option> -->
  <option integrator="implicitfast" impratio="20" cone="elliptic">
    <!-- <flag multiccd="enable"/> -->
  </option>
  <size njmax="2000" nconmax="2000" />

  <default>
    <default class="stretch">
      <geom mass="0" solref="0.005 1"/>
      <general biastype="affine"/>
      <default class="wheel">
        <joint axis="0 0 1" damping="0.1" frictionloss="35" armature="0.1" stiffness="0.01"/>
        <velocity gear="3" kv="20" ctrlrange="-6 6"/>
      </default>
      <default class="lift">
        <joint type="slide" axis="0 0 1" damping="35" stiffness="0.03" armature="0.01" range="0.0 1.1" frictionloss="1.5"/>
        <general ctrlrange="0.0 1.1" gainprm="400" biasprm="0 -200 -100" forcerange="-70 70"/>
      </default>
      <default class="telescope">
        <joint type="slide" axis="0 0 1" damping="50" stiffness="0.02" armature="0.01" range="0 0.13" frictionloss="1.5"/>
        <general ctrlrange="0 0.52" gainprm="150" biasprm="0 -100 -10" forcerange="-56 56"/>
      </default>
      <default class="head">
        <joint axis="0 0 1" damping="1"/>
        <position kp="10"/>
        <default class="head_pan">
          <joint range="-4.04 1.73"/>
          <position ctrlrange="-4.04 1.73"/>
        </default>
        <default class="head_tilt">
          <joint range="-1.53 0.79"/>
          <position ctrlrange="-1.53 0.79"/>
        </default>
      </default>

      <default class="wrist">
        <joint axis="0 0 1" damping="1"/>
        <position kp="10"/>
        <default class="wrist_yaw">
          <joint axis="0 0 -1" range="-1.39 4.42" armature="0.01" damping="7" frictionloss=".1"/>
          <position ctrlrange="-1.39 4.42" kp="20"/>
        </default>
        <default class="wrist_pitch">
          <joint axis="0 0 1" range="-1.57 0.56" armature="0.01" frictionloss=".1"/>
          <position ctrlrange="-1.57 0.56" kp="50"/>
        </default>
        <default class="wrist_roll">
          <joint axis="0 0 1" range="-3.14 3.14" armature="0.01" frictionloss=".1"/>
          <position ctrlrange="-3.14 3.14" kp="20"/>
        </default>
        <default class="finger_open">
          <joint axis="0 -1 0" range="-0.6 0.6" damping="0.0001" armature="0.01" frictionloss=".1"/>
          <position ctrlrange="-0.6 0.6" kp="4000" kv="124"/>
        </default>
        <default class="finger_slide">
          <joint type="slide" axis="0 0 1" range="-0.02 .04" armature="0.1" damping="0.0001"/>
          <position ctrlrange="-0.02 .04" kp="4000" kv="124"/>
        </default>
    </default>

      <default class="visual">
        <geom group="2" type="mesh" contype="0" conaffinity="0"/>
      </default>
      <default class="collision">
        <geom group="3" type="mesh"/>
        <default class="caster">
          <geom type="sphere" size=".02" pos="-0.24 0 .02" condim="1" priority="1"/>
        </default>
        <default class="rubber">
<geom condim="6" friction="500 5 20.0" priority="1" solref="0.02 1" solimp="0.99 0.99 0.01" conaffinity="1"/>
        </default>
      </default>
    </default>
  </default>

  <asset>
    <texture type="2d" file="hand_crush.png"/>
    <texture type="2d" file="serial.png"/>
    <texture type="2d" file="mobile_base_right_corner_aruco_sticker.png"/>
    <texture type="2d" file="mobile_base_left_corner_aruco_sticker.png"/>
    <texture type="2d" file="hand_pinch.png"/>
    <texture type="2d" file="arm_inner_wrist_aruco_sticker.png"/>
    <texture type="2d" file="arm_top_wrist_aruco_sticker.png"/>
    <texture type="2d" file="shoulder_aruco_sticker.png"/>
    <texture type="2d" file="right_finger_aruco.png"/>
    <texture type="2d" file="left_finger_aruco.png"/>
    <texture type="2d" file="gripper_cam_aruco_sticker.png"/>

    <material name="Caster_Rollers_Red" rgba="0.8 0.001381 0 1"/>
    <material name="Generic_Black" rgba="0.036889 0.036889 0.036889 1"/>
    <material name="3D_Print_Black" rgba="0.114435 0.114435 0.114435 1"/>
    <material name="Pantone_Black_6_U" rgba="0.072272 0.076185 0.093059 1"/>
    <material name="Plug_White" rgba="1 1 1 1"/>
    <material name="Pure_Black" rgba="0 0 0 1"/>
    <material name="Gray_Lens" rgba="0.3 0.3 0.3 1" reflectance="0.3"/>
    <material name="Reflective_Metal" rgba="0.8 0.8 0.8 1" reflectance="0.3" specular="0.5" shininess="0.25"/>
    <material name="Respeaker_Blue_Glow" rgba="0.006995 0.054480 0.799103 1"/>
    <material name="Runstop_White_Glow" rgba="0.8 0.8 0.8 1"/>
    <material name="Speaker_Housing_Black" rgba="0.003642 0.003642 0.003642 1"/>
    <material name="Wheel_Rubber_Gray" rgba="0.418986 0.424087 0.429225 1"/>
    <material name="Lightbar_Green" rgba="0.0 0.8 0.002964 1"/>
    <material name="Pantone_705_U" rgba="1 0.723054 0.760525 1"/>
    <material name="Pantone_Cool_Gray_4_U" rgba="0.473531 0.479320 0.485150 1"/>
    <material name="Power_Button_Green" rgba="0.010852 0.023650 0.002724 1"/>
    <material name="USB_Blue" rgba="0.000557 0.010166 0.8 1"/>
    <material name="White_Plastic" rgba="1 1 1 1" specular="0.5" shininess="0.25"/>
    <material name="Laser_Black" rgba="0.03741 0.03741 0.03741 1"/>
    <material name="Hand_Crush_Sticker" texture="hand_crush"/>
    <material name="Stretch_Serial_Sticker" texture="serial"/>
    <material name="Aruco_Right_Base_Sticker" texture="mobile_base_right_corner_aruco_sticker"/>
    <material name="Aruco_Left_Base_Sticker" texture="mobile_base_left_corner_aruco_sticker"/>
    <material name="Hand_Pinch_Sticker" texture="hand_pinch"/>
    <material name="Carbon_Fiber" rgba="0.061246 0.061246 0.061246 1"/>
    <material name="Aruco_Inner_Wrist_Sticker" texture="arm_inner_wrist_aruco_sticker"/>
    <material name="Aruco_Top_Wrist_Sticker" texture="arm_top_wrist_aruco_sticker"/>
    <material name="suction_rubber" rgba="0.25098 0.25098 0.25098 1"/>
    <material name="Aruco_Shoulder_Sticker" texture="shoulder_aruco_sticker"/>

    <material name="Aruco_right_finger_Sticker" texture="right_finger_aruco"/>
    <material name="Aruco_left_finger_Sticker" texture="left_finger_aruco"/>
    <material name="Aruco_gripper_cam_Sticker" texture="gripper_cam_aruco_sticker"/>

    <mesh file="base_link_0.obj"/>
    <mesh file="base_link_2.obj"/>
    <mesh file="base_link_3.obj"/>
    <mesh file="base_link_4.obj"/>
    <mesh file="base_link_5.obj"/>
    <mesh file="base_link_6.obj"/>
    <mesh file="base_link_7.obj"/>
    <mesh file="base_link_8.obj"/>
    <mesh name="base_link_collision" file="base_link_casterless.stl"/>
    <mesh file="link_aruco_right_base.obj"/>
    <mesh file="link_aruco_left_base.obj"/>
    <mesh file="respeaker_base.obj"/>
    <mesh file="link_mast.obj"/>
    <mesh file="link_head_0.obj"/>
    <mesh file="link_head_1.obj"/>
    <mesh file="link_head_2.obj"/>
    <mesh file="link_head_3.obj"/>
    <mesh file="link_head_4.obj"/>
    <mesh file="link_head_5.obj"/>
    <mesh file="link_head_6.obj"/>
    <mesh file="link_head_7.obj"/>
    <mesh file="link_head_8.obj"/>
    <mesh file="link_head_9.obj"/>
    <mesh file="link_head_10.obj"/>
    <mesh file="link_head_11.obj"/>
    <mesh file="link_head_pan_0.obj"/>
    <mesh file="link_head_pan_1.obj"/>
    <mesh file="link_head_tilt_0.obj"/>
    <mesh file="link_head_tilt_1.obj"/>
    <mesh file="link_right_wheel_0.obj"/>
    <mesh file="link_right_wheel_1.obj"/>
    <mesh file="link_left_wheel_0.obj"/>
    <mesh file="link_left_wheel_1.obj"/>
    <mesh file="link_lift_0.obj"/>
    <mesh file="link_lift_1.obj"/>
    <mesh file="link_lift_2.obj"/>
    <mesh file="link_lift_3.obj"/>
    <mesh file="link_lift_4.obj"/>
    <mesh file="link_lift_5.obj"/>
    <mesh file="link_lift_6.obj"/>
    <mesh file="link_lift_7.obj"/>
    <mesh file="link_lift_8.obj"/>
    <mesh file="link_lift_9.obj"/>
    <mesh file="link_aruco_shoulder.obj"/>
    <mesh file="link_arm_l4_0.obj"/>
    <mesh file="link_arm_l4_1.obj"/>
    <mesh file="link_arm_l3_0.obj"/>
    <mesh file="link_arm_l3_1.obj"/>
    <mesh file="link_arm_l2_0.obj"/>
    <mesh file="link_arm_l2_1.obj"/>
    <mesh file="link_arm_l1_0.obj"/>
    <mesh file="link_arm_l1_1.obj"/>
    <mesh file="link_arm_l0_0.obj"/>
    <mesh file="link_arm_l0_1.obj"/>
    <mesh file="link_arm_l0_2.obj"/>
    <mesh file="link_aruco_inner_wrist.obj"/>
    <mesh file="link_aruco_top_wrist.obj"/>
    <mesh file="laser.obj"/>
    <mesh file="link_gripper_fingertip_left.stl"/>
    <mesh file="link_gripper_fingertip_right.stl"/>
    <mesh file="link_gripper_finger_left_0.obj" scale="0.9 1 1"/>
    <mesh file="link_gripper_finger_left_1.obj" scale="0.9 1 1"/>
    <mesh file="link_gripper_finger_right_0.obj" scale="0.9 1 1"/>
    <mesh file="link_gripper_finger_right_1.obj" scale="0.9 1 1"/>
    <mesh file="link_gripper_0.obj"/>
    <mesh file="link_gripper_1.obj"/>
    <mesh file="link_wrist_yaw.obj"/>

    <mesh file="link_DW3_tablet_12in.stl"/>
    <mesh file="link_DW3_wrist_pitch.stl"/>
    <mesh file="link_DW3_wrist_quick_connect.stl"/>
    <mesh file="link_DW3_wrist_yaw_bottom.stl"/>
    <mesh file="link_SE3_head_nav_cam.stl"/>
    <mesh file="link_SG3_aruco_d405.obj"/>
    <mesh file="link_SG3_gripper_body.stl"/>

    <mesh file="link_d405.stl"/>
    <mesh file="link_d405_lens.stl"/>
    <mesh file="link_d405_front_plate.stl"/>

    <mesh file="link_SG3_gripper_left_finger.stl"/>
    <mesh file="link_SG3_gripper_right_finger.stl"/>

    <mesh file="link_SG3_gripper_left_finger_0.obj"/>
    <mesh file="link_SG3_gripper_right_finger_0.obj"/>
    <mesh file="link_SG3_gripper_left_finger_1.obj"/>
    <mesh file="link_SG3_gripper_right_finger_1.obj"/>

    <mesh file="link_SG3_gripper_left_inner_finger.stl"/>
    <mesh file="link_SG3_gripper_right_inner_finger.stl"/>

    <mesh file="link_SG3_gripper_inner_finger.stl"/>

    <mesh file="link_SG3_gripper_left_finger_aruco.obj"/>
    <mesh file="link_SG3_gripper_right_finger_aruco.obj"/>

    <mesh file="link_SG3_gripper_right_fingertip.stl"/>
    <mesh file="link_SG3_gripper_left_fingertip.stl"/>
  </asset>

  <worldbody>


    <geom name="pick_target" type="sphere" size="0.03" pos="100 100 0.001" rgba="0 1 0 0.0"/>

    <geom name="base_target" type="cylinder" size="0.1 0.001 0.1" pos="0 0 0.001" rgba="0 1 0 0.0" contype="0" conaffinity="0"/>
    <geom name="base_center" type="cylinder" size="0.1 0.001 0.1" pos="0 0 0.001" rgba="1 0 0 0.0" contype="0" conaffinity="0"/>


        <body name="body_extent" pos="100 100 100">
            <geom name="body_extent" type="box" size="0.39 0.31 0.15" rgba="0 1 0 0.2" contype="0" conaffinity="0"/>
        </body>





    
    <geom name="optimal_circle" type="cylinder" size="0.1 0.001 0.001" pos="100 100 0.001" rgba="0 1 0 0.3" contype="0" conaffinity="0"/>
    <geom name="optimal_norm" type="sphere" size="0.01" pos="100 100 0.001" rgba="0 1 0 0.3"  contype="0" conaffinity="0"/>

    <geom name="test_circle" type="cylinder" size="0.1 0.001 0.001" pos="100 100 0.001" rgba="0 0 1 0.3" contype="0" conaffinity="0"/>
    <geom name="test_norm" type="sphere" size="0.01" pos="100 100 0.001" rgba="0 0 1 0.3"  contype="0" conaffinity="0"/>
    
    <geom name="actual_norm" type="sphere" size="0.01" pos="100 100 0.001" rgba="1 0 0 0.3"  contype="0" conaffinity="0"/>
    <geom name="actual_circle" type="cylinder" size="0.1 0.001 0.001" pos="100 100 0.001" rgba="1 0 0 0.3" contype="0" conaffinity="0"/>
    <geom name="best_circle" type="sphere" size="0.1 0.01 0.01"  pos="100 100 0.001" rgba="1 0 0 0.3" contype="0" conaffinity="0"/>

    <geom name="traj_1" type="sphere" size="0.02" pos="100 100 0.001" rgba="1 1 0 0.5" contype="0" conaffinity="0"/>
    <geom name="traj_2" type="sphere" size="0.02" pos="100 100 0.001" rgba="1 1 0 0.5" contype="0" conaffinity="0"/>
    <geom name="traj_3" type="sphere" size="0.02" pos="100 100 0.001" rgba="1 1 0 0.5" contype="0" conaffinity="0"/>
    <geom name="traj_4" type="sphere" size="0.02" pos="100 100 0.001" rgba="1 1 0 0.5" contype="0" conaffinity="0"/>
    <geom name="traj_5" type="sphere" size="0.02" pos="100 100 0.001" rgba="1 1 0 0.5" contype="0" conaffinity="0"/>
    <geom name="traj_6" type="sphere" size="0.02" pos="100 100 0.001" rgba="1 1 0 0.5" contype="0" conaffinity="0"/>
    <geom name="traj_7" type="sphere" size="0.02" pos="100 100 0.001" rgba="1 1 0 0.5" contype="0" conaffinity="0"/>
    <geom name="traj_8" type="sphere" size="0.02" pos="100 100 0.001" rgba="1 1 0 0.5" contype="0" conaffinity="0"/>
    <geom name="traj_9" type="sphere" size="0.02" pos="100 100 0.001" rgba="1 1 0 0.5" contype="0" conaffinity="0"/>
    <geom name="traj_10" type="sphere" size="0.02" pos="100 100 0.001" rgba="1 1 0 0.5" contype="0" conaffinity="0"/>
    <geom name="traj_11" type="sphere" size="0.02" pos="100 100 0.001" rgba="1 1 0 0.5" contype="0" conaffinity="0"/>
    <geom name="traj_12" type="sphere" size="0.02" pos="100 100 0.001" rgba="1 1 0 0.5" contype="0" conaffinity="0"/>
    <geom name="traj_13" type="sphere" size="0.02" pos="100 100 0.001" rgba="1 1 0 0.5" contype="0" conaffinity="0"/>
    <geom name="traj_14" type="sphere" size="0.02" pos="100 100 0.001" rgba="1 1 0 0.5" contype="0" conaffinity="0"/>
    <geom name="traj_15" type="sphere" size="0.02" pos="100 100 0.001" rgba="1 1 0 0.5" contype="0" conaffinity="0"/>
    <geom name="traj_16" type="sphere" size="0.02" pos="100 100 0.001" rgba="1 1 0 0.5" contype="0" conaffinity="0"/>
    <geom name="traj_17" type="sphere" size="0.02" pos="100 100 0.001" rgba="1 1 0 0.5" contype="0" conaffinity="0"/>
    <geom name="traj_18" type="sphere" size="0.02" pos="100 100 0.001" rgba="1 1 0 0.5" contype="0" conaffinity="0"/>
    <geom name="traj_19" type="sphere" size="0.02" pos="100 100 0.001" rgba="1 1 0 0.5" contype="0" conaffinity="0"/>
    <geom name="traj_20" type="sphere" size="0.02" pos="100 100 0.001" rgba="1 1 0 0.5" contype="0" conaffinity="0"/>
    <geom name="traj_21" type="sphere" size="0.02" pos="100 100 0.001" rgba="1 1 0 0.5" contype="0" conaffinity="0"/>





    <geom name="test_1" type="sphere" size="0.02" pos="100 100 0.001" rgba="0.8 0.7 0.6 0.5" contype="0" conaffinity="0"/>
    <geom name="test_2" type="sphere" size="0.02" pos="100 100 0.001" rgba="0.8 0.7 0.6 0.5" contype="0" conaffinity="0"/>
    <geom name="test_3" type="sphere" size="0.02" pos="100 100 0.001" rgba="0.8 0.7 0.6 0.5" contype="0" conaffinity="0"/>
    <geom name="test_4" type="sphere" size="0.02" pos="100 100 0.001" rgba="0.8 0.7 0.6 0.5" contype="0" conaffinity="0"/>
    <geom name="test_5" type="sphere" size="0.02" pos="100 100 0.001" rgba="0.8 0.7 0.6 0.5" contype="0" conaffinity="0"/>
    <geom name="test_6" type="sphere" size="0.02" pos="100 100 0.001" rgba="0.8 0.7 0.6 0.5" contype="0" conaffinity="0"/>
    <geom name="test_7" type="sphere" size="0.02" pos="100 100 0.001" rgba="0.8 0.7 0.6 0.5" contype="0" conaffinity="0"/>
    <geom name="test_8" type="sphere" size="0.02" pos="100 100 0.001" rgba="0.8 0.7 0.6 0.5" contype="0" conaffinity="0"/>
    <geom name="test_9" type="sphere" size="0.02" pos="100 100 0.001" rgba="0.8 0.7 0.6 0.5" contype="0" conaffinity="0"/>
    <geom name="test_10" type="sphere" size="0.02" pos="100 100 0.001" rgba="0.8 0.7 0.6 0.5" contype="0" conaffinity="0"/>
    <geom name="test_11" type="sphere" size="0.02" pos="100 100 0.001" rgba="0.8 0.7 0.6 0.5" contype="0" conaffinity="0"/>




    <body name="grasping_head_0" pos="19 91 91">
      <geom name="center_0" type="cylinder" size="0.003 0.015" pos="0.0 0.0 -0.028" rgba="0 0 1 1" contype="0" conaffinity="0"/>
      <geom name="cylinder_left_0" type="cylinder" size="0.003 0.02" pos="0.032 0 0.006" rgba="0 0 1 1" contype="0" conaffinity="0"/>
      <geom name="cylinder_right_0" type="cylinder" size="0.003 0.02" pos="-0.032 0 0.006" rgba="0 0 1 1" contype="0" conaffinity="0"/>
      <geom name="connecting_bar_0" type="box" size="0.03 0.002 0.002" pos="0 0 -0.012" rgba="0 0 1 1" contype="0" conaffinity="0"/>
    </body>
        
    
    <body name="grasping_head_1" pos="19 91 91">
      <geom name="center_1" type="cylinder" size="0.003 0.015" pos="0.0 0.0 -0.028" rgba="0 0 1 1" contype="0" conaffinity="0"/>
      <geom name="cylinder_left_1" type="cylinder" size="0.003 0.02" pos="0.032 0 0.006" rgba="0 0 1 1" contype="0" conaffinity="0"/>
      <geom name="cylinder_right_1" type="cylinder" size="0.003 0.02" pos="-0.032 0 0.006" rgba="0 0 1 1" contype="0" conaffinity="0"/>
      <geom name="connecting_bar_1" type="box" size="0.03 0.002 0.002" pos="0 0 -0.012" rgba="0 0 1 1" contype="0" conaffinity="0"/>
    </body>
        
    
    <body name="grasping_head_2" pos="19 91 91">
      <geom name="center_2" type="cylinder" size="0.003 0.015" pos="0.0 0.0 -0.028" rgba="0 0 1 1" contype="0" conaffinity="0"/>
      <geom name="cylinder_left_2" type="cylinder" size="0.003 0.02" pos="0.032 0 0.006" rgba="0 0 1 1" contype="0" conaffinity="0"/>
      <geom name="cylinder_right_2" type="cylinder" size="0.003 0.02" pos="-0.032 0 0.006" rgba="0 0 1 1" contype="0" conaffinity="0"/>
      <geom name="connecting_bar_2" type="box" size="0.03 0.002 0.002" pos="0 0 -0.012" rgba="0 0 1 1" contype="0" conaffinity="0"/>
    </body>
        
    
    <body name="grasping_head_3" pos="19 91 91">
      <geom name="center_3" type="cylinder" size="0.003 0.015" pos="0.0 0.0 -0.028" rgba="0 0 1 1" contype="0" conaffinity="0"/>
      <geom name="cylinder_left_3" type="cylinder" size="0.003 0.02" pos="0.032 0 0.006" rgba="0 0 1 1" contype="0" conaffinity="0"/>
      <geom name="cylinder_right_3" type="cylinder" size="0.003 0.02" pos="-0.032 0 0.006" rgba="0 0 1 1" contype="0" conaffinity="0"/>
      <geom name="connecting_bar_3" type="box" size="0.03 0.002 0.002" pos="0 0 -0.012" rgba="0 0 1 1" contype="0" conaffinity="0"/>
    </body>
        
    
    <body name="grasping_head_4" pos="19 91 91">
      <geom name="center_4" type="cylinder" size="0.003 0.015" pos="0.0 0.0 -0.028" rgba="0 0 1 1" contype="0" conaffinity="0"/>
      <geom name="cylinder_left_4" type="cylinder" size="0.003 0.02" pos="0.032 0 0.006" rgba="0 0 1 1" contype="0" conaffinity="0"/>
      <geom name="cylinder_right_4" type="cylinder" size="0.003 0.02" pos="-0.032 0 0.006" rgba="0 0 1 1" contype="0" conaffinity="0"/>
      <geom name="connecting_bar_4" type="box" size="0.03 0.002 0.002" pos="0 0 -0.012" rgba="0 0 1 1" contype="0" conaffinity="0"/>
    </body>
        
    
    <body name="grasping_head_5" pos="19 91 91">
      <geom name="center_5" type="cylinder" size="0.003 0.015" pos="0.0 0.0 -0.028" rgba="0 0 1 1" contype="0" conaffinity="0"/>
      <geom name="cylinder_left_5" type="cylinder" size="0.003 0.02" pos="0.032 0 0.006" rgba="0 0 1 1" contype="0" conaffinity="0"/>
      <geom name="cylinder_right_5" type="cylinder" size="0.003 0.02" pos="-0.032 0 0.006" rgba="0 0 1 1" contype="0" conaffinity="0"/>
      <geom name="connecting_bar_5" type="box" size="0.03 0.002 0.002" pos="0 0 -0.012" rgba="0 0 1 1" contype="0" conaffinity="0"/>
    </body>
        
    
    <body name="grasping_head_6" pos="19 91 91">
      <geom name="center_6" type="cylinder" size="0.003 0.015" pos="0.0 0.0 -0.028" rgba="0 0 1 1" contype="0" conaffinity="0"/>
      <geom name="cylinder_left_6" type="cylinder" size="0.003 0.02" pos="0.032 0 0.006" rgba="0 0 1 1" contype="0" conaffinity="0"/>
      <geom name="cylinder_right_6" type="cylinder" size="0.003 0.02" pos="-0.032 0 0.006" rgba="0 0 1 1" contype="0" conaffinity="0"/>
      <geom name="connecting_bar_6" type="box" size="0.03 0.002 0.002" pos="0 0 -0.012" rgba="0 0 1 1" contype="0" conaffinity="0"/>
    </body>
        
    
    <body name="grasping_head_7" pos="19 91 91">
      <geom name="center_7" type="cylinder" size="0.003 0.015" pos="0.0 0.0 -0.028" rgba="0 0 1 1" contype="0" conaffinity="0"/>
      <geom name="cylinder_left_7" type="cylinder" size="0.003 0.02" pos="0.032 0 0.006" rgba="0 0 1 1" contype="0" conaffinity="0"/>
      <geom name="cylinder_right_7" type="cylinder" size="0.003 0.02" pos="-0.032 0 0.006" rgba="0 0 1 1" contype="0" conaffinity="0"/>
      <geom name="connecting_bar_7" type="box" size="0.03 0.002 0.002" pos="0 0 -0.012" rgba="0 0 1 1" contype="0" conaffinity="0"/>
    </body>
        
    
    <body name="grasping_head_8" pos="19 91 91">
      <geom name="center_8" type="cylinder" size="0.003 0.015" pos="0.0 0.0 -0.028" rgba="0 0 1 1" contype="0" conaffinity="0"/>
      <geom name="cylinder_left_8" type="cylinder" size="0.003 0.02" pos="0.032 0 0.006" rgba="0 0 1 1" contype="0" conaffinity="0"/>
      <geom name="cylinder_right_8" type="cylinder" size="0.003 0.02" pos="-0.032 0 0.006" rgba="0 0 1 1" contype="0" conaffinity="0"/>
      <geom name="connecting_bar_8" type="box" size="0.03 0.002 0.002" pos="0 0 -0.012" rgba="0 0 1 1" contype="0" conaffinity="0"/>
    </body>
        
    
    <body name="grasping_head_9" pos="19 91 91">
      <geom name="center_9" type="cylinder" size="0.003 0.015" pos="0.0 0.0 -0.028" rgba="0 0 1 1" contype="0" conaffinity="0"/>
      <geom name="cylinder_left_9" type="cylinder" size="0.003 0.02" pos="0.032 0 0.006" rgba="0 0 1 1" contype="0" conaffinity="0"/>
      <geom name="cylinder_right_9" type="cylinder" size="0.003 0.02" pos="-0.032 0 0.006" rgba="0 0 1 1" contype="0" conaffinity="0"/>
      <geom name="connecting_bar_9" type="box" size="0.03 0.002 0.002" pos="0 0 -0.012" rgba="0 0 1 1" contype="0" conaffinity="0"/>
    </body>
        
    
    <body name="grasping_head_10" pos="19 91 91">
      <geom name="center_10" type="cylinder" size="0.003 0.015" pos="0.0 0.0 -0.028" rgba="0 0 1 1" contype="0" conaffinity="0"/>
      <geom name="cylinder_left_10" type="cylinder" size="0.003 0.02" pos="0.032 0 0.006" rgba="0 0 1 1" contype="0" conaffinity="0"/>
      <geom name="cylinder_right_10" type="cylinder" size="0.003 0.02" pos="-0.032 0 0.006" rgba="0 0 1 1" contype="0" conaffinity="0"/>
      <geom name="connecting_bar_10" type="box" size="0.03 0.002 0.002" pos="0 0 -0.012" rgba="0 0 1 1" contype="0" conaffinity="0"/>
    </body>
        
    
    <body name="grasping_head_11" pos="19 91 91">
      <geom name="center_11" type="cylinder" size="0.003 0.015" pos="0.0 0.0 -0.028" rgba="0 0 1 1" contype="0" conaffinity="0"/>
      <geom name="cylinder_left_11" type="cylinder" size="0.003 0.02" pos="0.032 0 0.006" rgba="0 0 1 1" contype="0" conaffinity="0"/>
      <geom name="cylinder_right_11" type="cylinder" size="0.003 0.02" pos="-0.032 0 0.006" rgba="0 0 1 1" contype="0" conaffinity="0"/>
      <geom name="connecting_bar_11" type="box" size="0.03 0.002 0.002" pos="0 0 -0.012" rgba="0 0 1 1" contype="0" conaffinity="0"/>
    </body>
        
    
    <body name="grasping_head_12" pos="19 91 91">
      <geom name="center_12" type="cylinder" size="0.003 0.015" pos="0.0 0.0 -0.028" rgba="0 0 1 1" contype="0" conaffinity="0"/>
      <geom name="cylinder_left_12" type="cylinder" size="0.003 0.02" pos="0.032 0 0.006" rgba="0 0 1 1" contype="0" conaffinity="0"/>
      <geom name="cylinder_right_12" type="cylinder" size="0.003 0.02" pos="-0.032 0 0.006" rgba="0 0 1 1" contype="0" conaffinity="0"/>
      <geom name="connecting_bar_12" type="box" size="0.03 0.002 0.002" pos="0 0 -0.012" rgba="0 0 1 1" contype="0" conaffinity="0"/>
    </body>
        
    
    <body name="grasping_head_13" pos="19 91 91">
      <geom name="center_13" type="cylinder" size="0.003 0.015" pos="0.0 0.0 -0.028" rgba="0 0 1 1" contype="0" conaffinity="0"/>
      <geom name="cylinder_left_13" type="cylinder" size="0.003 0.02" pos="0.032 0 0.006" rgba="0 0 1 1" contype="0" conaffinity="0"/>
      <geom name="cylinder_right_13" type="cylinder" size="0.003 0.02" pos="-0.032 0 0.006" rgba="0 0 1 1" contype="0" conaffinity="0"/>
      <geom name="connecting_bar_13" type="box" size="0.03 0.002 0.002" pos="0 0 -0.012" rgba="0 0 1 1" contype="0" conaffinity="0"/>
    </body>
        
    
    <body name="grasping_head_14" pos="19 91 91">
      <geom name="center_14" type="cylinder" size="0.003 0.015" pos="0.0 0.0 -0.028" rgba="0 0 1 1" contype="0" conaffinity="0"/>
      <geom name="cylinder_left_14" type="cylinder" size="0.003 0.02" pos="0.032 0 0.006" rgba="0 0 1 1" contype="0" conaffinity="0"/>
      <geom name="cylinder_right_14" type="cylinder" size="0.003 0.02" pos="-0.032 0 0.006" rgba="0 0 1 1" contype="0" conaffinity="0"/>
      <geom name="connecting_bar_14" type="box" size="0.03 0.002 0.002" pos="0 0 -0.012" rgba="0 0 1 1" contype="0" conaffinity="0"/>
    </body>
        
    
    <body name="grasping_head_15" pos="19 91 91">
      <geom name="center_15" type="cylinder" size="0.003 0.015" pos="0.0 0.0 -0.028" rgba="0 0 1 1" contype="0" conaffinity="0"/>
      <geom name="cylinder_left_15" type="cylinder" size="0.003 0.02" pos="0.032 0 0.006" rgba="0 0 1 1" contype="0" conaffinity="0"/>
      <geom name="cylinder_right_15" type="cylinder" size="0.003 0.02" pos="-0.032 0 0.006" rgba="0 0 1 1" contype="0" conaffinity="0"/>
      <geom name="connecting_bar_15" type="box" size="0.03 0.002 0.002" pos="0 0 -0.012" rgba="0 0 1 1" contype="0" conaffinity="0"/>
    </body>
        
    
    <body name="grasping_head_16" pos="19 91 91">
      <geom name="center_16" type="cylinder" size="0.003 0.015" pos="0.0 0.0 -0.028" rgba="0 0 1 1" contype="0" conaffinity="0"/>
      <geom name="cylinder_left_16" type="cylinder" size="0.003 0.02" pos="0.032 0 0.006" rgba="0 0 1 1" contype="0" conaffinity="0"/>
      <geom name="cylinder_right_16" type="cylinder" size="0.003 0.02" pos="-0.032 0 0.006" rgba="0 0 1 1" contype="0" conaffinity="0"/>
      <geom name="connecting_bar_16" type="box" size="0.03 0.002 0.002" pos="0 0 -0.012" rgba="0 0 1 1" contype="0" conaffinity="0"/>
    </body>
        
    
    <body name="grasping_head_17" pos="19 91 91">
      <geom name="center_17" type="cylinder" size="0.003 0.015" pos="0.0 0.0 -0.028" rgba="0 0 1 1" contype="0" conaffinity="0"/>
      <geom name="cylinder_left_17" type="cylinder" size="0.003 0.02" pos="0.032 0 0.006" rgba="0 0 1 1" contype="0" conaffinity="0"/>
      <geom name="cylinder_right_17" type="cylinder" size="0.003 0.02" pos="-0.032 0 0.006" rgba="0 0 1 1" contype="0" conaffinity="0"/>
      <geom name="connecting_bar_17" type="box" size="0.03 0.002 0.002" pos="0 0 -0.012" rgba="0 0 1 1" contype="0" conaffinity="0"/>
    </body>
        
    
    <body name="grasping_head_18" pos="19 91 91">
      <geom name="center_18" type="cylinder" size="0.003 0.015" pos="0.0 0.0 -0.028" rgba="0 0 1 1" contype="0" conaffinity="0"/>
      <geom name="cylinder_left_18" type="cylinder" size="0.003 0.02" pos="0.032 0 0.006" rgba="0 0 1 1" contype="0" conaffinity="0"/>
      <geom name="cylinder_right_18" type="cylinder" size="0.003 0.02" pos="-0.032 0 0.006" rgba="0 0 1 1" contype="0" conaffinity="0"/>
      <geom name="connecting_bar_18" type="box" size="0.03 0.002 0.002" pos="0 0 -0.012" rgba="0 0 1 1" contype="0" conaffinity="0"/>
    </body>
        
    
    <body name="grasping_head_19" pos="19 91 91">
      <geom name="center_19" type="cylinder" size="0.003 0.015" pos="0.0 0.0 -0.028" rgba="0 0 1 1" contype="0" conaffinity="0"/>
      <geom name="cylinder_left_19" type="cylinder" size="0.003 0.02" pos="0.032 0 0.006" rgba="0 0 1 1" contype="0" conaffinity="0"/>
      <geom name="cylinder_right_19" type="cylinder" size="0.003 0.02" pos="-0.032 0 0.006" rgba="0 0 1 1" contype="0" conaffinity="0"/>
      <geom name="connecting_bar_19" type="box" size="0.03 0.002 0.002" pos="0 0 -0.012" rgba="0 0 1 1" contype="0" conaffinity="0"/>
    </body>
        
    
    <body name="grasping_head_20" pos="19 91 91">
      <geom name="center_20" type="cylinder" size="0.003 0.015" pos="0.0 0.0 -0.028" rgba="0 0 1 1" contype="0" conaffinity="0"/>
      <geom name="cylinder_left_20" type="cylinder" size="0.003 0.02" pos="0.032 0 0.006" rgba="0 0 1 1" contype="0" conaffinity="0"/>
      <geom name="cylinder_right_20" type="cylinder" size="0.003 0.02" pos="-0.032 0 0.006" rgba="0 0 1 1" contype="0" conaffinity="0"/>
      <geom name="connecting_bar_20" type="box" size="0.03 0.002 0.002" pos="0 0 -0.012" rgba="0 0 1 1" contype="0" conaffinity="0"/>
    </body>
        
    
    <body name="grasping_head_21" pos="19 91 91">
      <geom name="center_21" type="cylinder" size="0.003 0.015" pos="0.0 0.0 -0.028" rgba="0 0 1 1" contype="0" conaffinity="0"/>
      <geom name="cylinder_left_21" type="cylinder" size="0.003 0.02" pos="0.032 0 0.006" rgba="0 0 1 1" contype="0" conaffinity="0"/>
      <geom name="cylinder_right_21" type="cylinder" size="0.003 0.02" pos="-0.032 0 0.006" rgba="0 0 1 1" contype="0" conaffinity="0"/>
      <geom name="connecting_bar_21" type="box" size="0.03 0.002 0.002" pos="0 0 -0.012" rgba="0 0 1 1" contype="0" conaffinity="0"/>
    </body>
        
    
    <body name="grasping_head_22" pos="19 91 91">
      <geom name="center_22" type="cylinder" size="0.003 0.015" pos="0.0 0.0 -0.028" rgba="0 0 1 1" contype="0" conaffinity="0"/>
      <geom name="cylinder_left_22" type="cylinder" size="0.003 0.02" pos="0.032 0 0.006" rgba="0 0 1 1" contype="0" conaffinity="0"/>
      <geom name="cylinder_right_22" type="cylinder" size="0.003 0.02" pos="-0.032 0 0.006" rgba="0 0 1 1" contype="0" conaffinity="0"/>
      <geom name="connecting_bar_22" type="box" size="0.03 0.002 0.002" pos="0 0 -0.012" rgba="0 0 1 1" contype="0" conaffinity="0"/>
    </body>
        
    
    <body name="grasping_head_23" pos="19 91 91">
      <geom name="center_23" type="cylinder" size="0.003 0.015" pos="0.0 0.0 -0.028" rgba="0 0 1 1" contype="0" conaffinity="0"/>
      <geom name="cylinder_left_23" type="cylinder" size="0.003 0.02" pos="0.032 0 0.006" rgba="0 0 1 1" contype="0" conaffinity="0"/>
      <geom name="cylinder_right_23" type="cylinder" size="0.003 0.02" pos="-0.032 0 0.006" rgba="0 0 1 1" contype="0" conaffinity="0"/>
      <geom name="connecting_bar_23" type="box" size="0.03 0.002 0.002" pos="0 0 -0.012" rgba="0 0 1 1" contype="0" conaffinity="0"/>
    </body>
        
    
    <body name="grasping_head_24" pos="19 91 91">
      <geom name="center_24" type="cylinder" size="0.003 0.015" pos="0.0 0.0 -0.028" rgba="0 0 1 1" contype="0" conaffinity="0"/>
      <geom name="cylinder_left_24" type="cylinder" size="0.003 0.02" pos="0.032 0 0.006" rgba="0 0 1 1" contype="0" conaffinity="0"/>
      <geom name="cylinder_right_24" type="cylinder" size="0.003 0.02" pos="-0.032 0 0.006" rgba="0 0 1 1" contype="0" conaffinity="0"/>
      <geom name="connecting_bar_24" type="box" size="0.03 0.002 0.002" pos="0 0 -0.012" rgba="0 0 1 1" contype="0" conaffinity="0"/>
    </body>
        
    
    <body name="grasping_head_25" pos="19 91 91">
      <geom name="center_25" type="cylinder" size="0.003 0.015" pos="0.0 0.0 -0.028" rgba="0 0 1 1" contype="0" conaffinity="0"/>
      <geom name="cylinder_left_25" type="cylinder" size="0.003 0.02" pos="0.032 0 0.006" rgba="0 0 1 1" contype="0" conaffinity="0"/>
      <geom name="cylinder_right_25" type="cylinder" size="0.003 0.02" pos="-0.032 0 0.006" rgba="0 0 1 1" contype="0" conaffinity="0"/>
      <geom name="connecting_bar_25" type="box" size="0.03 0.002 0.002" pos="0 0 -0.012" rgba="0 0 1 1" contype="0" conaffinity="0"/>
    </body>
        
    
    <body name="grasping_head_26" pos="19 91 91">
      <geom name="center_26" type="cylinder" size="0.003 0.015" pos="0.0 0.0 -0.028" rgba="0 0 1 1" contype="0" conaffinity="0"/>
      <geom name="cylinder_left_26" type="cylinder" size="0.003 0.02" pos="0.032 0 0.006" rgba="0 0 1 1" contype="0" conaffinity="0"/>
      <geom name="cylinder_right_26" type="cylinder" size="0.003 0.02" pos="-0.032 0 0.006" rgba="0 0 1 1" contype="0" conaffinity="0"/>
      <geom name="connecting_bar_26" type="box" size="0.03 0.002 0.002" pos="0 0 -0.012" rgba="0 0 1 1" contype="0" conaffinity="0"/>
    </body>
        
    
    <body name="grasping_head_27" pos="19 91 91">
      <geom name="center_27" type="cylinder" size="0.003 0.015" pos="0.0 0.0 -0.028" rgba="0 0 1 1" contype="0" conaffinity="0"/>
      <geom name="cylinder_left_27" type="cylinder" size="0.003 0.02" pos="0.032 0 0.006" rgba="0 0 1 1" contype="0" conaffinity="0"/>
      <geom name="cylinder_right_27" type="cylinder" size="0.003 0.02" pos="-0.032 0 0.006" rgba="0 0 1 1" contype="0" conaffinity="0"/>
      <geom name="connecting_bar_27" type="box" size="0.03 0.002 0.002" pos="0 0 -0.012" rgba="0 0 1 1" contype="0" conaffinity="0"/>
    </body>
        
    
    <body name="grasping_head_28" pos="19 91 91">
      <geom name="center_28" type="cylinder" size="0.003 0.015" pos="0.0 0.0 -0.028" rgba="0 0 1 1" contype="0" conaffinity="0"/>
      <geom name="cylinder_left_28" type="cylinder" size="0.003 0.02" pos="0.032 0 0.006" rgba="0 0 1 1" contype="0" conaffinity="0"/>
      <geom name="cylinder_right_28" type="cylinder" size="0.003 0.02" pos="-0.032 0 0.006" rgba="0 0 1 1" contype="0" conaffinity="0"/>
      <geom name="connecting_bar_28" type="box" size="0.03 0.002 0.002" pos="0 0 -0.012" rgba="0 0 1 1" contype="0" conaffinity="0"/>
    </body>
        
    
    <body name="grasping_head_29" pos="19 91 91">
      <geom name="center_29" type="cylinder" size="0.003 0.015" pos="0.0 0.0 -0.028" rgba="0 0 1 1" contype="0" conaffinity="0"/>
      <geom name="cylinder_left_29" type="cylinder" size="0.003 0.02" pos="0.032 0 0.006" rgba="0 0 1 1" contype="0" conaffinity="0"/>
      <geom name="cylinder_right_29" type="cylinder" size="0.003 0.02" pos="-0.032 0 0.006" rgba="0 0 1 1" contype="0" conaffinity="0"/>
      <geom name="connecting_bar_29" type="box" size="0.03 0.002 0.002" pos="0 0 -0.012" rgba="0 0 1 1" contype="0" conaffinity="0"/>
    </body>
        
    
    <body name="grasping_head_30" pos="19 91 91">
      <geom name="center_30" type="cylinder" size="0.003 0.015" pos="0.0 0.0 -0.028" rgba="0 0 1 1" contype="0" conaffinity="0"/>
      <geom name="cylinder_left_30" type="cylinder" size="0.003 0.02" pos="0.032 0 0.006" rgba="0 0 1 1" contype="0" conaffinity="0"/>
      <geom name="cylinder_right_30" type="cylinder" size="0.003 0.02" pos="-0.032 0 0.006" rgba="0 0 1 1" contype="0" conaffinity="0"/>
      <geom name="connecting_bar_30" type="box" size="0.03 0.002 0.002" pos="0 0 -0.012" rgba="0 0 1 1" contype="0" conaffinity="0"/>
    </body>
        
    
    <body name="grasping_head_31" pos="19 91 91">
      <geom name="center_31" type="cylinder" size="0.003 0.015" pos="0.0 0.0 -0.028" rgba="0 0 1 1" contype="0" conaffinity="0"/>
      <geom name="cylinder_left_31" type="cylinder" size="0.003 0.02" pos="0.032 0 0.006" rgba="0 0 1 1" contype="0" conaffinity="0"/>
      <geom name="cylinder_right_31" type="cylinder" size="0.003 0.02" pos="-0.032 0 0.006" rgba="0 0 1 1" contype="0" conaffinity="0"/>
      <geom name="connecting_bar_31" type="box" size="0.03 0.002 0.002" pos="0 0 -0.012" rgba="0 0 1 1" contype="0" conaffinity="0"/>
    </body>
        
    
    <body name="grasping_head_32" pos="19 91 91">
      <geom name="center_32" type="cylinder" size="0.003 0.015" pos="0.0 0.0 -0.028" rgba="0 0 1 1" contype="0" conaffinity="0"/>
      <geom name="cylinder_left_32" type="cylinder" size="0.003 0.02" pos="0.032 0 0.006" rgba="0 0 1 1" contype="0" conaffinity="0"/>
      <geom name="cylinder_right_32" type="cylinder" size="0.003 0.02" pos="-0.032 0 0.006" rgba="0 0 1 1" contype="0" conaffinity="0"/>
      <geom name="connecting_bar_32" type="box" size="0.03 0.002 0.002" pos="0 0 -0.012" rgba="0 0 1 1" contype="0" conaffinity="0"/>
    </body>
        
    
    <body name="grasping_head_33" pos="19 91 91">
      <geom name="center_33" type="cylinder" size="0.003 0.015" pos="0.0 0.0 -0.028" rgba="0 0 1 1" contype="0" conaffinity="0"/>
      <geom name="cylinder_left_33" type="cylinder" size="0.003 0.02" pos="0.032 0 0.006" rgba="0 0 1 1" contype="0" conaffinity="0"/>
      <geom name="cylinder_right_33" type="cylinder" size="0.003 0.02" pos="-0.032 0 0.006" rgba="0 0 1 1" contype="0" conaffinity="0"/>
      <geom name="connecting_bar_33" type="box" size="0.03 0.002 0.002" pos="0 0 -0.012" rgba="0 0 1 1" contype="0" conaffinity="0"/>
    </body>
        
    
    <body name="grasping_head_34" pos="19 91 91">
      <geom name="center_34" type="cylinder" size="0.003 0.015" pos="0.0 0.0 -0.028" rgba="0 0 1 1" contype="0" conaffinity="0"/>
      <geom name="cylinder_left_34" type="cylinder" size="0.003 0.02" pos="0.032 0 0.006" rgba="0 0 1 1" contype="0" conaffinity="0"/>
      <geom name="cylinder_right_34" type="cylinder" size="0.003 0.02" pos="-0.032 0 0.006" rgba="0 0 1 1" contype="0" conaffinity="0"/>
      <geom name="connecting_bar_34" type="box" size="0.03 0.002 0.002" pos="0 0 -0.012" rgba="0 0 1 1" contype="0" conaffinity="0"/>
    </body>
        
    
    <body name="grasping_head_35" pos="19 91 91">
      <geom name="center_35" type="cylinder" size="0.003 0.015" pos="0.0 0.0 -0.028" rgba="0 0 1 1" contype="0" conaffinity="0"/>
      <geom name="cylinder_left_35" type="cylinder" size="0.003 0.02" pos="0.032 0 0.006" rgba="0 0 1 1" contype="0" conaffinity="0"/>
      <geom name="cylinder_right_35" type="cylinder" size="0.003 0.02" pos="-0.032 0 0.006" rgba="0 0 1 1" contype="0" conaffinity="0"/>
      <geom name="connecting_bar_35" type="box" size="0.03 0.002 0.002" pos="0 0 -0.012" rgba="0 0 1 1" contype="0" conaffinity="0"/>
    </body>
        
    
    <body name="grasping_head_36" pos="19 91 91">
      <geom name="center_36" type="cylinder" size="0.003 0.015" pos="0.0 0.0 -0.028" rgba="0 0 1 1" contype="0" conaffinity="0"/>
      <geom name="cylinder_left_36" type="cylinder" size="0.003 0.02" pos="0.032 0 0.006" rgba="0 0 1 1" contype="0" conaffinity="0"/>
      <geom name="cylinder_right_36" type="cylinder" size="0.003 0.02" pos="-0.032 0 0.006" rgba="0 0 1 1" contype="0" conaffinity="0"/>
      <geom name="connecting_bar_36" type="box" size="0.03 0.002 0.002" pos="0 0 -0.012" rgba="0 0 1 1" contype="0" conaffinity="0"/>
    </body>
        
    
    <body name="grasping_head_37" pos="19 91 91">
      <geom name="center_37" type="cylinder" size="0.003 0.015" pos="0.0 0.0 -0.028" rgba="0 0 1 1" contype="0" conaffinity="0"/>
      <geom name="cylinder_left_37" type="cylinder" size="0.003 0.02" pos="0.032 0 0.006" rgba="0 0 1 1" contype="0" conaffinity="0"/>
      <geom name="cylinder_right_37" type="cylinder" size="0.003 0.02" pos="-0.032 0 0.006" rgba="0 0 1 1" contype="0" conaffinity="0"/>
      <geom name="connecting_bar_37" type="box" size="0.03 0.002 0.002" pos="0 0 -0.012" rgba="0 0 1 1" contype="0" conaffinity="0"/>
    </body>
        
    
    <body name="grasping_head_38" pos="19 91 91">
      <geom name="center_38" type="cylinder" size="0.003 0.015" pos="0.0 0.0 -0.028" rgba="0 0 1 1" contype="0" conaffinity="0"/>
      <geom name="cylinder_left_38" type="cylinder" size="0.003 0.02" pos="0.032 0 0.006" rgba="0 0 1 1" contype="0" conaffinity="0"/>
      <geom name="cylinder_right_38" type="cylinder" size="0.003 0.02" pos="-0.032 0 0.006" rgba="0 0 1 1" contype="0" conaffinity="0"/>
      <geom name="connecting_bar_38" type="box" size="0.03 0.002 0.002" pos="0 0 -0.012" rgba="0 0 1 1" contype="0" conaffinity="0"/>
    </body>
        
    
    <body name="grasping_head_39" pos="19 91 91">
      <geom name="center_39" type="cylinder" size="0.003 0.015" pos="0.0 0.0 -0.028" rgba="0 0 1 1" contype="0" conaffinity="0"/>
      <geom name="cylinder_left_39" type="cylinder" size="0.003 0.02" pos="0.032 0 0.006" rgba="0 0 1 1" contype="0" conaffinity="0"/>
      <geom name="cylinder_right_39" type="cylinder" size="0.003 0.02" pos="-0.032 0 0.006" rgba="0 0 1 1" contype="0" conaffinity="0"/>
      <geom name="connecting_bar_39" type="box" size="0.03 0.002 0.002" pos="0 0 -0.012" rgba="0 0 1 1" contype="0" conaffinity="0"/>
    </body>
        
    
    <body name="grasping_head_40" pos="19 91 91">
      <geom name="center_40" type="cylinder" size="0.003 0.015" pos="0.0 0.0 -0.028" rgba="0 0 1 1" contype="0" conaffinity="0"/>
      <geom name="cylinder_left_40" type="cylinder" size="0.003 0.02" pos="0.032 0 0.006" rgba="0 0 1 1" contype="0" conaffinity="0"/>
      <geom name="cylinder_right_40" type="cylinder" size="0.003 0.02" pos="-0.032 0 0.006" rgba="0 0 1 1" contype="0" conaffinity="0"/>
      <geom name="connecting_bar_40" type="box" size="0.03 0.002 0.002" pos="0 0 -0.012" rgba="0 0 1 1" contype="0" conaffinity="0"/>
    </body>
        
    
    <body name="grasping_head_41" pos="19 91 91">
      <geom name="center_41" type="cylinder" size="0.003 0.015" pos="0.0 0.0 -0.028" rgba="0 0 1 1" contype="0" conaffinity="0"/>
      <geom name="cylinder_left_41" type="cylinder" size="0.003 0.02" pos="0.032 0 0.006" rgba="0 0 1 1" contype="0" conaffinity="0"/>
      <geom name="cylinder_right_41" type="cylinder" size="0.003 0.02" pos="-0.032 0 0.006" rgba="0 0 1 1" contype="0" conaffinity="0"/>
      <geom name="connecting_bar_41" type="box" size="0.03 0.002 0.002" pos="0 0 -0.012" rgba="0 0 1 1" contype="0" conaffinity="0"/>
    </body>
        
    
    <body name="grasping_head_42" pos="19 91 91">
      <geom name="center_42" type="cylinder" size="0.003 0.015" pos="0.0 0.0 -0.028" rgba="0 0 1 1" contype="0" conaffinity="0"/>
      <geom name="cylinder_left_42" type="cylinder" size="0.003 0.02" pos="0.032 0 0.006" rgba="0 0 1 1" contype="0" conaffinity="0"/>
      <geom name="cylinder_right_42" type="cylinder" size="0.003 0.02" pos="-0.032 0 0.006" rgba="0 0 1 1" contype="0" conaffinity="0"/>
      <geom name="connecting_bar_42" type="box" size="0.03 0.002 0.002" pos="0 0 -0.012" rgba="0 0 1 1" contype="0" conaffinity="0"/>
    </body>
        
    
    <body name="grasping_head_43" pos="19 91 91">
      <geom name="center_43" type="cylinder" size="0.003 0.015" pos="0.0 0.0 -0.028" rgba="0 0 1 1" contype="0" conaffinity="0"/>
      <geom name="cylinder_left_43" type="cylinder" size="0.003 0.02" pos="0.032 0 0.006" rgba="0 0 1 1" contype="0" conaffinity="0"/>
      <geom name="cylinder_right_43" type="cylinder" size="0.003 0.02" pos="-0.032 0 0.006" rgba="0 0 1 1" contype="0" conaffinity="0"/>
      <geom name="connecting_bar_43" type="box" size="0.03 0.002 0.002" pos="0 0 -0.012" rgba="0 0 1 1" contype="0" conaffinity="0"/>
    </body>
        
    
    <body name="grasping_head_44" pos="19 91 91">
      <geom name="center_44" type="cylinder" size="0.003 0.015" pos="0.0 0.0 -0.028" rgba="0 0 1 1" contype="0" conaffinity="0"/>
      <geom name="cylinder_left_44" type="cylinder" size="0.003 0.02" pos="0.032 0 0.006" rgba="0 0 1 1" contype="0" conaffinity="0"/>
      <geom name="cylinder_right_44" type="cylinder" size="0.003 0.02" pos="-0.032 0 0.006" rgba="0 0 1 1" contype="0" conaffinity="0"/>
      <geom name="connecting_bar_44" type="box" size="0.03 0.002 0.002" pos="0 0 -0.012" rgba="0 0 1 1" contype="0" conaffinity="0"/>
    </body>
        
    
    <body name="grasping_head_45" pos="19 91 91">
      <geom name="center_45" type="cylinder" size="0.003 0.015" pos="0.0 0.0 -0.028" rgba="0 0 1 1" contype="0" conaffinity="0"/>
      <geom name="cylinder_left_45" type="cylinder" size="0.003 0.02" pos="0.032 0 0.006" rgba="0 0 1 1" contype="0" conaffinity="0"/>
      <geom name="cylinder_right_45" type="cylinder" size="0.003 0.02" pos="-0.032 0 0.006" rgba="0 0 1 1" contype="0" conaffinity="0"/>
      <geom name="connecting_bar_45" type="box" size="0.03 0.002 0.002" pos="0 0 -0.012" rgba="0 0 1 1" contype="0" conaffinity="0"/>
    </body>
        
    
    <body name="grasping_head_46" pos="19 91 91">
      <geom name="center_46" type="cylinder" size="0.003 0.015" pos="0.0 0.0 -0.028" rgba="0 0 1 1" contype="0" conaffinity="0"/>
      <geom name="cylinder_left_46" type="cylinder" size="0.003 0.02" pos="0.032 0 0.006" rgba="0 0 1 1" contype="0" conaffinity="0"/>
      <geom name="cylinder_right_46" type="cylinder" size="0.003 0.02" pos="-0.032 0 0.006" rgba="0 0 1 1" contype="0" conaffinity="0"/>
      <geom name="connecting_bar_46" type="box" size="0.03 0.002 0.002" pos="0 0 -0.012" rgba="0 0 1 1" contype="0" conaffinity="0"/>
    </body>
        
    
    <body name="grasping_head_47" pos="19 91 91">
      <geom name="center_47" type="cylinder" size="0.003 0.015" pos="0.0 0.0 -0.028" rgba="0 0 1 1" contype="0" conaffinity="0"/>
      <geom name="cylinder_left_47" type="cylinder" size="0.003 0.02" pos="0.032 0 0.006" rgba="0 0 1 1" contype="0" conaffinity="0"/>
      <geom name="cylinder_right_47" type="cylinder" size="0.003 0.02" pos="-0.032 0 0.006" rgba="0 0 1 1" contype="0" conaffinity="0"/>
      <geom name="connecting_bar_47" type="box" size="0.03 0.002 0.002" pos="0 0 -0.012" rgba="0 0 1 1" contype="0" conaffinity="0"/>
    </body>
        
    
    <body name="grasping_head_48" pos="19 91 91">
      <geom name="center_48" type="cylinder" size="0.003 0.015" pos="0.0 0.0 -0.028" rgba="0 0 1 1" contype="0" conaffinity="0"/>
      <geom name="cylinder_left_48" type="cylinder" size="0.003 0.02" pos="0.032 0 0.006" rgba="0 0 1 1" contype="0" conaffinity="0"/>
      <geom name="cylinder_right_48" type="cylinder" size="0.003 0.02" pos="-0.032 0 0.006" rgba="0 0 1 1" contype="0" conaffinity="0"/>
      <geom name="connecting_bar_48" type="box" size="0.03 0.002 0.002" pos="0 0 -0.012" rgba="0 0 1 1" contype="0" conaffinity="0"/>
    </body>
        
    
    <body name="grasping_head_49" pos="19 91 91">
      <geom name="center_49" type="cylinder" size="0.003 0.015" pos="0.0 0.0 -0.028" rgba="0 0 1 1" contype="0" conaffinity="0"/>
      <geom name="cylinder_left_49" type="cylinder" size="0.003 0.02" pos="0.032 0 0.006" rgba="0 0 1 1" contype="0" conaffinity="0"/>
      <geom name="cylinder_right_49" type="cylinder" size="0.003 0.02" pos="-0.032 0 0.006" rgba="0 0 1 1" contype="0" conaffinity="0"/>
      <geom name="connecting_bar_49" type="box" size="0.03 0.002 0.002" pos="0 0 -0.012" rgba="0 0 1 1" contype="0" conaffinity="0"/>
    </body>
        
    
    <body name="grasping_head_50" pos="19 91 91">
      <geom name="center_50" type="cylinder" size="0.003 0.015" pos="0.0 0.0 -0.028" rgba="0 0 1 1" contype="0" conaffinity="0"/>
      <geom name="cylinder_left_50" type="cylinder" size="0.003 0.02" pos="0.032 0 0.006" rgba="0 0 1 1" contype="0" conaffinity="0"/>
      <geom name="cylinder_right_50" type="cylinder" size="0.003 0.02" pos="-0.032 0 0.006" rgba="0 0 1 1" contype="0" conaffinity="0"/>
      <geom name="connecting_bar_50" type="box" size="0.03 0.002 0.002" pos="0 0 -0.012" rgba="0 0 1 1" contype="0" conaffinity="0"/>
    </body>
        
    
    <body name="grasping_head_51" pos="19 91 91">
      <geom name="center_51" type="cylinder" size="0.003 0.015" pos="0.0 0.0 -0.028" rgba="0 0 1 1" contype="0" conaffinity="0"/>
      <geom name="cylinder_left_51" type="cylinder" size="0.003 0.02" pos="0.032 0 0.006" rgba="0 0 1 1" contype="0" conaffinity="0"/>
      <geom name="cylinder_right_51" type="cylinder" size="0.003 0.02" pos="-0.032 0 0.006" rgba="0 0 1 1" contype="0" conaffinity="0"/>
      <geom name="connecting_bar_51" type="box" size="0.03 0.002 0.002" pos="0 0 -0.012" rgba="0 0 1 1" contype="0" conaffinity="0"/>
    </body>
        
    
    <body name="grasping_head_52" pos="19 91 91">
      <geom name="center_52" type="cylinder" size="0.003 0.015" pos="0.0 0.0 -0.028" rgba="0 0 1 1" contype="0" conaffinity="0"/>
      <geom name="cylinder_left_52" type="cylinder" size="0.003 0.02" pos="0.032 0 0.006" rgba="0 0 1 1" contype="0" conaffinity="0"/>
      <geom name="cylinder_right_52" type="cylinder" size="0.003 0.02" pos="-0.032 0 0.006" rgba="0 0 1 1" contype="0" conaffinity="0"/>
      <geom name="connecting_bar_52" type="box" size="0.03 0.002 0.002" pos="0 0 -0.012" rgba="0 0 1 1" contype="0" conaffinity="0"/>
    </body>
        
    
    <body name="grasping_head_53" pos="19 91 91">
      <geom name="center_53" type="cylinder" size="0.003 0.015" pos="0.0 0.0 -0.028" rgba="0 0 1 1" contype="0" conaffinity="0"/>
      <geom name="cylinder_left_53" type="cylinder" size="0.003 0.02" pos="0.032 0 0.006" rgba="0 0 1 1" contype="0" conaffinity="0"/>
      <geom name="cylinder_right_53" type="cylinder" size="0.003 0.02" pos="-0.032 0 0.006" rgba="0 0 1 1" contype="0" conaffinity="0"/>
      <geom name="connecting_bar_53" type="box" size="0.03 0.002 0.002" pos="0 0 -0.012" rgba="0 0 1 1" contype="0" conaffinity="0"/>
    </body>
        
    
    <body name="grasping_head_54" pos="19 91 91">
      <geom name="center_54" type="cylinder" size="0.003 0.015" pos="0.0 0.0 -0.028" rgba="0 0 1 1" contype="0" conaffinity="0"/>
      <geom name="cylinder_left_54" type="cylinder" size="0.003 0.02" pos="0.032 0 0.006" rgba="0 0 1 1" contype="0" conaffinity="0"/>
      <geom name="cylinder_right_54" type="cylinder" size="0.003 0.02" pos="-0.032 0 0.006" rgba="0 0 1 1" contype="0" conaffinity="0"/>
      <geom name="connecting_bar_54" type="box" size="0.03 0.002 0.002" pos="0 0 -0.012" rgba="0 0 1 1" contype="0" conaffinity="0"/>
    </body>
        
    
    <body name="grasping_head_55" pos="19 91 91">
      <geom name="center_55" type="cylinder" size="0.003 0.015" pos="0.0 0.0 -0.028" rgba="0 0 1 1" contype="0" conaffinity="0"/>
      <geom name="cylinder_left_55" type="cylinder" size="0.003 0.02" pos="0.032 0 0.006" rgba="0 0 1 1" contype="0" conaffinity="0"/>
      <geom name="cylinder_right_55" type="cylinder" size="0.003 0.02" pos="-0.032 0 0.006" rgba="0 0 1 1" contype="0" conaffinity="0"/>
      <geom name="connecting_bar_55" type="box" size="0.03 0.002 0.002" pos="0 0 -0.012" rgba="0 0 1 1" contype="0" conaffinity="0"/>
    </body>
        
    
    <body name="grasping_head_56" pos="19 91 91">
      <geom name="center_56" type="cylinder" size="0.003 0.015" pos="0.0 0.0 -0.028" rgba="0 0 1 1" contype="0" conaffinity="0"/>
      <geom name="cylinder_left_56" type="cylinder" size="0.003 0.02" pos="0.032 0 0.006" rgba="0 0 1 1" contype="0" conaffinity="0"/>
      <geom name="cylinder_right_56" type="cylinder" size="0.003 0.02" pos="-0.032 0 0.006" rgba="0 0 1 1" contype="0" conaffinity="0"/>
      <geom name="connecting_bar_56" type="box" size="0.03 0.002 0.002" pos="0 0 -0.012" rgba="0 0 1 1" contype="0" conaffinity="0"/>
    </body>
        
    
    <body name="grasping_head_57" pos="19 91 91">
      <geom name="center_57" type="cylinder" size="0.003 0.015" pos="0.0 0.0 -0.028" rgba="0 0 1 1" contype="0" conaffinity="0"/>
      <geom name="cylinder_left_57" type="cylinder" size="0.003 0.02" pos="0.032 0 0.006" rgba="0 0 1 1" contype="0" conaffinity="0"/>
      <geom name="cylinder_right_57" type="cylinder" size="0.003 0.02" pos="-0.032 0 0.006" rgba="0 0 1 1" contype="0" conaffinity="0"/>
      <geom name="connecting_bar_57" type="box" size="0.03 0.002 0.002" pos="0 0 -0.012" rgba="0 0 1 1" contype="0" conaffinity="0"/>
    </body>
        
    
    <body name="grasping_head_58" pos="19 91 91">
      <geom name="center_58" type="cylinder" size="0.003 0.015" pos="0.0 0.0 -0.028" rgba="0 0 1 1" contype="0" conaffinity="0"/>
      <geom name="cylinder_left_58" type="cylinder" size="0.003 0.02" pos="0.032 0 0.006" rgba="0 0 1 1" contype="0" conaffinity="0"/>
      <geom name="cylinder_right_58" type="cylinder" size="0.003 0.02" pos="-0.032 0 0.006" rgba="0 0 1 1" contype="0" conaffinity="0"/>
      <geom name="connecting_bar_58" type="box" size="0.03 0.002 0.002" pos="0 0 -0.012" rgba="0 0 1 1" contype="0" conaffinity="0"/>
    </body>
        
    
    <body name="grasping_head_59" pos="19 91 91">
      <geom name="center_59" type="cylinder" size="0.003 0.015" pos="0.0 0.0 -0.028" rgba="0 0 1 1" contype="0" conaffinity="0"/>
      <geom name="cylinder_left_59" type="cylinder" size="0.003 0.02" pos="0.032 0 0.006" rgba="0 0 1 1" contype="0" conaffinity="0"/>
      <geom name="cylinder_right_59" type="cylinder" size="0.003 0.02" pos="-0.032 0 0.006" rgba="0 0 1 1" contype="0" conaffinity="0"/>
      <geom name="connecting_bar_59" type="box" size="0.03 0.002 0.002" pos="0 0 -0.012" rgba="0 0 1 1" contype="0" conaffinity="0"/>
    </body>
        
    
    <body name="grasping_head_60" pos="19 91 91">
      <geom name="center_60" type="cylinder" size="0.003 0.015" pos="0.0 0.0 -0.028" rgba="0 0 1 1" contype="0" conaffinity="0"/>
      <geom name="cylinder_left_60" type="cylinder" size="0.003 0.02" pos="0.032 0 0.006" rgba="0 0 1 1" contype="0" conaffinity="0"/>
      <geom name="cylinder_right_60" type="cylinder" size="0.003 0.02" pos="-0.032 0 0.006" rgba="0 0 1 1" contype="0" conaffinity="0"/>
      <geom name="connecting_bar_60" type="box" size="0.03 0.002 0.002" pos="0 0 -0.012" rgba="0 0 1 1" contype="0" conaffinity="0"/>
    </body>
        
    
    <body name="grasping_head_61" pos="19 91 91">
      <geom name="center_61" type="cylinder" size="0.003 0.015" pos="0.0 0.0 -0.028" rgba="0 0 1 1" contype="0" conaffinity="0"/>
      <geom name="cylinder_left_61" type="cylinder" size="0.003 0.02" pos="0.032 0 0.006" rgba="0 0 1 1" contype="0" conaffinity="0"/>
      <geom name="cylinder_right_61" type="cylinder" size="0.003 0.02" pos="-0.032 0 0.006" rgba="0 0 1 1" contype="0" conaffinity="0"/>
      <geom name="connecting_bar_61" type="box" size="0.03 0.002 0.002" pos="0 0 -0.012" rgba="0 0 1 1" contype="0" conaffinity="0"/>
    </body>
        
    
    <body name="grasping_head_62" pos="19 91 91">
      <geom name="center_62" type="cylinder" size="0.003 0.015" pos="0.0 0.0 -0.028" rgba="0 0 1 1" contype="0" conaffinity="0"/>
      <geom name="cylinder_left_62" type="cylinder" size="0.003 0.02" pos="0.032 0 0.006" rgba="0 0 1 1" contype="0" conaffinity="0"/>
      <geom name="cylinder_right_62" type="cylinder" size="0.003 0.02" pos="-0.032 0 0.006" rgba="0 0 1 1" contype="0" conaffinity="0"/>
      <geom name="connecting_bar_62" type="box" size="0.03 0.002 0.002" pos="0 0 -0.012" rgba="0 0 1 1" contype="0" conaffinity="0"/>
    </body>
        
    
    <body name="grasping_head_63" pos="19 91 91">
      <geom name="center_63" type="cylinder" size="0.003 0.015" pos="0.0 0.0 -0.028" rgba="0 0 1 1" contype="0" conaffinity="0"/>
      <geom name="cylinder_left_63" type="cylinder" size="0.003 0.02" pos="0.032 0 0.006" rgba="0 0 1 1" contype="0" conaffinity="0"/>
      <geom name="cylinder_right_63" type="cylinder" size="0.003 0.02" pos="-0.032 0 0.006" rgba="0 0 1 1" contype="0" conaffinity="0"/>
      <geom name="connecting_bar_63" type="box" size="0.03 0.002 0.002" pos="0 0 -0.012" rgba="0 0 1 1" contype="0" conaffinity="0"/>
    </body>
        
    
    <body name="grasping_head_64" pos="19 91 91">
      <geom name="center_64" type="cylinder" size="0.003 0.015" pos="0.0 0.0 -0.028" rgba="0 0 1 1" contype="0" conaffinity="0"/>
      <geom name="cylinder_left_64" type="cylinder" size="0.003 0.02" pos="0.032 0 0.006" rgba="0 0 1 1" contype="0" conaffinity="0"/>
      <geom name="cylinder_right_64" type="cylinder" size="0.003 0.02" pos="-0.032 0 0.006" rgba="0 0 1 1" contype="0" conaffinity="0"/>
      <geom name="connecting_bar_64" type="box" size="0.03 0.002 0.002" pos="0 0 -0.012" rgba="0 0 1 1" contype="0" conaffinity="0"/>
    </body>
        
    
    <body name="grasping_head_65" pos="19 91 91">
      <geom name="center_65" type="cylinder" size="0.003 0.015" pos="0.0 0.0 -0.028" rgba="0 0 1 1" contype="0" conaffinity="0"/>
      <geom name="cylinder_left_65" type="cylinder" size="0.003 0.02" pos="0.032 0 0.006" rgba="0 0 1 1" contype="0" conaffinity="0"/>
      <geom name="cylinder_right_65" type="cylinder" size="0.003 0.02" pos="-0.032 0 0.006" rgba="0 0 1 1" contype="0" conaffinity="0"/>
      <geom name="connecting_bar_65" type="box" size="0.03 0.002 0.002" pos="0 0 -0.012" rgba="0 0 1 1" contype="0" conaffinity="0"/>
    </body>
        
    
    <body name="grasping_head_66" pos="19 91 91">
      <geom name="center_66" type="cylinder" size="0.003 0.015" pos="0.0 0.0 -0.028" rgba="0 0 1 1" contype="0" conaffinity="0"/>
      <geom name="cylinder_left_66" type="cylinder" size="0.003 0.02" pos="0.032 0 0.006" rgba="0 0 1 1" contype="0" conaffinity="0"/>
      <geom name="cylinder_right_66" type="cylinder" size="0.003 0.02" pos="-0.032 0 0.006" rgba="0 0 1 1" contype="0" conaffinity="0"/>
      <geom name="connecting_bar_66" type="box" size="0.03 0.002 0.002" pos="0 0 -0.012" rgba="0 0 1 1" contype="0" conaffinity="0"/>
    </body>
        
    
    <body name="grasping_head_67" pos="19 91 91">
      <geom name="center_67" type="cylinder" size="0.003 0.015" pos="0.0 0.0 -0.028" rgba="0 0 1 1" contype="0" conaffinity="0"/>
      <geom name="cylinder_left_67" type="cylinder" size="0.003 0.02" pos="0.032 0 0.006" rgba="0 0 1 1" contype="0" conaffinity="0"/>
      <geom name="cylinder_right_67" type="cylinder" size="0.003 0.02" pos="-0.032 0 0.006" rgba="0 0 1 1" contype="0" conaffinity="0"/>
      <geom name="connecting_bar_67" type="box" size="0.03 0.002 0.002" pos="0 0 -0.012" rgba="0 0 1 1" contype="0" conaffinity="0"/>
    </body>
        
    
    <body name="grasping_head_68" pos="19 91 91">
      <geom name="center_68" type="cylinder" size="0.003 0.015" pos="0.0 0.0 -0.028" rgba="0 0 1 1" contype="0" conaffinity="0"/>
      <geom name="cylinder_left_68" type="cylinder" size="0.003 0.02" pos="0.032 0 0.006" rgba="0 0 1 1" contype="0" conaffinity="0"/>
      <geom name="cylinder_right_68" type="cylinder" size="0.003 0.02" pos="-0.032 0 0.006" rgba="0 0 1 1" contype="0" conaffinity="0"/>
      <geom name="connecting_bar_68" type="box" size="0.03 0.002 0.002" pos="0 0 -0.012" rgba="0 0 1 1" contype="0" conaffinity="0"/>
    </body>
        
    
    <body name="grasping_head_69" pos="19 91 91">
      <geom name="center_69" type="cylinder" size="0.003 0.015" pos="0.0 0.0 -0.028" rgba="0 0 1 1" contype="0" conaffinity="0"/>
      <geom name="cylinder_left_69" type="cylinder" size="0.003 0.02" pos="0.032 0 0.006" rgba="0 0 1 1" contype="0" conaffinity="0"/>
      <geom name="cylinder_right_69" type="cylinder" size="0.003 0.02" pos="-0.032 0 0.006" rgba="0 0 1 1" contype="0" conaffinity="0"/>
      <geom name="connecting_bar_69" type="box" size="0.03 0.002 0.002" pos="0 0 -0.012" rgba="0 0 1 1" contype="0" conaffinity="0"/>
    </body>
        
    
    <body name="grasping_head_70" pos="19 91 91">
      <geom name="center_70" type="cylinder" size="0.003 0.015" pos="0.0 0.0 -0.028" rgba="0 0 1 1" contype="0" conaffinity="0"/>
      <geom name="cylinder_left_70" type="cylinder" size="0.003 0.02" pos="0.032 0 0.006" rgba="0 0 1 1" contype="0" conaffinity="0"/>
      <geom name="cylinder_right_70" type="cylinder" size="0.003 0.02" pos="-0.032 0 0.006" rgba="0 0 1 1" contype="0" conaffinity="0"/>
      <geom name="connecting_bar_70" type="box" size="0.03 0.002 0.002" pos="0 0 -0.012" rgba="0 0 1 1" contype="0" conaffinity="0"/>
    </body>
        
    
    <body name="grasping_head_71" pos="19 91 91">
      <geom name="center_71" type="cylinder" size="0.003 0.015" pos="0.0 0.0 -0.028" rgba="0 0 1 1" contype="0" conaffinity="0"/>
      <geom name="cylinder_left_71" type="cylinder" size="0.003 0.02" pos="0.032 0 0.006" rgba="0 0 1 1" contype="0" conaffinity="0"/>
      <geom name="cylinder_right_71" type="cylinder" size="0.003 0.02" pos="-0.032 0 0.006" rgba="0 0 1 1" contype="0" conaffinity="0"/>
      <geom name="connecting_bar_71" type="box" size="0.03 0.002 0.002" pos="0 0 -0.012" rgba="0 0 1 1" contype="0" conaffinity="0"/>
    </body>
        
    
    <body name="grasping_head_72" pos="19 91 91">
      <geom name="center_72" type="cylinder" size="0.003 0.015" pos="0.0 0.0 -0.028" rgba="0 0 1 1" contype="0" conaffinity="0"/>
      <geom name="cylinder_left_72" type="cylinder" size="0.003 0.02" pos="0.032 0 0.006" rgba="0 0 1 1" contype="0" conaffinity="0"/>
      <geom name="cylinder_right_72" type="cylinder" size="0.003 0.02" pos="-0.032 0 0.006" rgba="0 0 1 1" contype="0" conaffinity="0"/>
      <geom name="connecting_bar_72" type="box" size="0.03 0.002 0.002" pos="0 0 -0.012" rgba="0 0 1 1" contype="0" conaffinity="0"/>
    </body>
        
    
    <body name="grasping_head_73" pos="19 91 91">
      <geom name="center_73" type="cylinder" size="0.003 0.015" pos="0.0 0.0 -0.028" rgba="0 0 1 1" contype="0" conaffinity="0"/>
      <geom name="cylinder_left_73" type="cylinder" size="0.003 0.02" pos="0.032 0 0.006" rgba="0 0 1 1" contype="0" conaffinity="0"/>
      <geom name="cylinder_right_73" type="cylinder" size="0.003 0.02" pos="-0.032 0 0.006" rgba="0 0 1 1" contype="0" conaffinity="0"/>
      <geom name="connecting_bar_73" type="box" size="0.03 0.002 0.002" pos="0 0 -0.012" rgba="0 0 1 1" contype="0" conaffinity="0"/>
    </body>
        
    
    <body name="grasping_head_74" pos="19 91 91">
      <geom name="center_74" type="cylinder" size="0.003 0.015" pos="0.0 0.0 -0.028" rgba="0 0 1 1" contype="0" conaffinity="0"/>
      <geom name="cylinder_left_74" type="cylinder" size="0.003 0.02" pos="0.032 0 0.006" rgba="0 0 1 1" contype="0" conaffinity="0"/>
      <geom name="cylinder_right_74" type="cylinder" size="0.003 0.02" pos="-0.032 0 0.006" rgba="0 0 1 1" contype="0" conaffinity="0"/>
      <geom name="connecting_bar_74" type="box" size="0.03 0.002 0.002" pos="0 0 -0.012" rgba="0 0 1 1" contype="0" conaffinity="0"/>
    </body>
        
    
    <body name="grasping_head_75" pos="19 91 91">
      <geom name="center_75" type="cylinder" size="0.003 0.015" pos="0.0 0.0 -0.028" rgba="0 0 1 1" contype="0" conaffinity="0"/>
      <geom name="cylinder_left_75" type="cylinder" size="0.003 0.02" pos="0.032 0 0.006" rgba="0 0 1 1" contype="0" conaffinity="0"/>
      <geom name="cylinder_right_75" type="cylinder" size="0.003 0.02" pos="-0.032 0 0.006" rgba="0 0 1 1" contype="0" conaffinity="0"/>
      <geom name="connecting_bar_75" type="box" size="0.03 0.002 0.002" pos="0 0 -0.012" rgba="0 0 1 1" contype="0" conaffinity="0"/>
    </body>
        
    
    <body name="grasping_head_76" pos="19 91 91">
      <geom name="center_76" type="cylinder" size="0.003 0.015" pos="0.0 0.0 -0.028" rgba="0 0 1 1" contype="0" conaffinity="0"/>
      <geom name="cylinder_left_76" type="cylinder" size="0.003 0.02" pos="0.032 0 0.006" rgba="0 0 1 1" contype="0" conaffinity="0"/>
      <geom name="cylinder_right_76" type="cylinder" size="0.003 0.02" pos="-0.032 0 0.006" rgba="0 0 1 1" contype="0" conaffinity="0"/>
      <geom name="connecting_bar_76" type="box" size="0.03 0.002 0.002" pos="0 0 -0.012" rgba="0 0 1 1" contype="0" conaffinity="0"/>
    </body>
        
    
    <body name="grasping_head_77" pos="19 91 91">
      <geom name="center_77" type="cylinder" size="0.003 0.015" pos="0.0 0.0 -0.028" rgba="0 0 1 1" contype="0" conaffinity="0"/>
      <geom name="cylinder_left_77" type="cylinder" size="0.003 0.02" pos="0.032 0 0.006" rgba="0 0 1 1" contype="0" conaffinity="0"/>
      <geom name="cylinder_right_77" type="cylinder" size="0.003 0.02" pos="-0.032 0 0.006" rgba="0 0 1 1" contype="0" conaffinity="0"/>
      <geom name="connecting_bar_77" type="box" size="0.03 0.002 0.002" pos="0 0 -0.012" rgba="0 0 1 1" contype="0" conaffinity="0"/>
    </body>
        
    
    <body name="grasping_head_78" pos="19 91 91">
      <geom name="center_78" type="cylinder" size="0.003 0.015" pos="0.0 0.0 -0.028" rgba="0 0 1 1" contype="0" conaffinity="0"/>
      <geom name="cylinder_left_78" type="cylinder" size="0.003 0.02" pos="0.032 0 0.006" rgba="0 0 1 1" contype="0" conaffinity="0"/>
      <geom name="cylinder_right_78" type="cylinder" size="0.003 0.02" pos="-0.032 0 0.006" rgba="0 0 1 1" contype="0" conaffinity="0"/>
      <geom name="connecting_bar_78" type="box" size="0.03 0.002 0.002" pos="0 0 -0.012" rgba="0 0 1 1" contype="0" conaffinity="0"/>
    </body>
        
    
    <body name="grasping_head_79" pos="19 91 91">
      <geom name="center_79" type="cylinder" size="0.003 0.015" pos="0.0 0.0 -0.028" rgba="0 0 1 1" contype="0" conaffinity="0"/>
      <geom name="cylinder_left_79" type="cylinder" size="0.003 0.02" pos="0.032 0 0.006" rgba="0 0 1 1" contype="0" conaffinity="0"/>
      <geom name="cylinder_right_79" type="cylinder" size="0.003 0.02" pos="-0.032 0 0.006" rgba="0 0 1 1" contype="0" conaffinity="0"/>
      <geom name="connecting_bar_79" type="box" size="0.03 0.002 0.002" pos="0 0 -0.012" rgba="0 0 1 1" contype="0" conaffinity="0"/>
    </body>
        
    
    <body name="grasping_head_80" pos="19 91 91">
      <geom name="center_80" type="cylinder" size="0.003 0.015" pos="0.0 0.0 -0.028" rgba="0 0 1 1" contype="0" conaffinity="0"/>
      <geom name="cylinder_left_80" type="cylinder" size="0.003 0.02" pos="0.032 0 0.006" rgba="0 0 1 1" contype="0" conaffinity="0"/>
      <geom name="cylinder_right_80" type="cylinder" size="0.003 0.02" pos="-0.032 0 0.006" rgba="0 0 1 1" contype="0" conaffinity="0"/>
      <geom name="connecting_bar_80" type="box" size="0.03 0.002 0.002" pos="0 0 -0.012" rgba="0 0 1 1" contype="0" conaffinity="0"/>
    </body>
        
    
    <body name="grasping_head_81" pos="19 91 91">
      <geom name="center_81" type="cylinder" size="0.003 0.015" pos="0.0 0.0 -0.028" rgba="0 0 1 1" contype="0" conaffinity="0"/>
      <geom name="cylinder_left_81" type="cylinder" size="0.003 0.02" pos="0.032 0 0.006" rgba="0 0 1 1" contype="0" conaffinity="0"/>
      <geom name="cylinder_right_81" type="cylinder" size="0.003 0.02" pos="-0.032 0 0.006" rgba="0 0 1 1" contype="0" conaffinity="0"/>
      <geom name="connecting_bar_81" type="box" size="0.03 0.002 0.002" pos="0 0 -0.012" rgba="0 0 1 1" contype="0" conaffinity="0"/>
    </body>
        
    
    <body name="grasping_head_82" pos="19 91 91">
      <geom name="center_82" type="cylinder" size="0.003 0.015" pos="0.0 0.0 -0.028" rgba="0 0 1 1" contype="0" conaffinity="0"/>
      <geom name="cylinder_left_82" type="cylinder" size="0.003 0.02" pos="0.032 0 0.006" rgba="0 0 1 1" contype="0" conaffinity="0"/>
      <geom name="cylinder_right_82" type="cylinder" size="0.003 0.02" pos="-0.032 0 0.006" rgba="0 0 1 1" contype="0" conaffinity="0"/>
      <geom name="connecting_bar_82" type="box" size="0.03 0.002 0.002" pos="0 0 -0.012" rgba="0 0 1 1" contype="0" conaffinity="0"/>
    </body>
        
    
    <body name="grasping_head_83" pos="19 91 91">
      <geom name="center_83" type="cylinder" size="0.003 0.015" pos="0.0 0.0 -0.028" rgba="0 0 1 1" contype="0" conaffinity="0"/>
      <geom name="cylinder_left_83" type="cylinder" size="0.003 0.02" pos="0.032 0 0.006" rgba="0 0 1 1" contype="0" conaffinity="0"/>
      <geom name="cylinder_right_83" type="cylinder" size="0.003 0.02" pos="-0.032 0 0.006" rgba="0 0 1 1" contype="0" conaffinity="0"/>
      <geom name="connecting_bar_83" type="box" size="0.03 0.002 0.002" pos="0 0 -0.012" rgba="0 0 1 1" contype="0" conaffinity="0"/>
    </body>
        
    
    <body name="grasping_head_84" pos="19 91 91">
      <geom name="center_84" type="cylinder" size="0.003 0.015" pos="0.0 0.0 -0.028" rgba="0 0 1 1" contype="0" conaffinity="0"/>
      <geom name="cylinder_left_84" type="cylinder" size="0.003 0.02" pos="0.032 0 0.006" rgba="0 0 1 1" contype="0" conaffinity="0"/>
      <geom name="cylinder_right_84" type="cylinder" size="0.003 0.02" pos="-0.032 0 0.006" rgba="0 0 1 1" contype="0" conaffinity="0"/>
      <geom name="connecting_bar_84" type="box" size="0.03 0.002 0.002" pos="0 0 -0.012" rgba="0 0 1 1" contype="0" conaffinity="0"/>
    </body>
        
    
    <body name="grasping_head_85" pos="19 91 91">
      <geom name="center_85" type="cylinder" size="0.003 0.015" pos="0.0 0.0 -0.028" rgba="0 0 1 1" contype="0" conaffinity="0"/>
      <geom name="cylinder_left_85" type="cylinder" size="0.003 0.02" pos="0.032 0 0.006" rgba="0 0 1 1" contype="0" conaffinity="0"/>
      <geom name="cylinder_right_85" type="cylinder" size="0.003 0.02" pos="-0.032 0 0.006" rgba="0 0 1 1" contype="0" conaffinity="0"/>
      <geom name="connecting_bar_85" type="box" size="0.03 0.002 0.002" pos="0 0 -0.012" rgba="0 0 1 1" contype="0" conaffinity="0"/>
    </body>
        
    
    <body name="grasping_head_86" pos="19 91 91">
      <geom name="center_86" type="cylinder" size="0.003 0.015" pos="0.0 0.0 -0.028" rgba="0 0 1 1" contype="0" conaffinity="0"/>
      <geom name="cylinder_left_86" type="cylinder" size="0.003 0.02" pos="0.032 0 0.006" rgba="0 0 1 1" contype="0" conaffinity="0"/>
      <geom name="cylinder_right_86" type="cylinder" size="0.003 0.02" pos="-0.032 0 0.006" rgba="0 0 1 1" contype="0" conaffinity="0"/>
      <geom name="connecting_bar_86" type="box" size="0.03 0.002 0.002" pos="0 0 -0.012" rgba="0 0 1 1" contype="0" conaffinity="0"/>
    </body>
        
    
    <body name="grasping_head_87" pos="19 91 91">
      <geom name="center_87" type="cylinder" size="0.003 0.015" pos="0.0 0.0 -0.028" rgba="0 0 1 1" contype="0" conaffinity="0"/>
      <geom name="cylinder_left_87" type="cylinder" size="0.003 0.02" pos="0.032 0 0.006" rgba="0 0 1 1" contype="0" conaffinity="0"/>
      <geom name="cylinder_right_87" type="cylinder" size="0.003 0.02" pos="-0.032 0 0.006" rgba="0 0 1 1" contype="0" conaffinity="0"/>
      <geom name="connecting_bar_87" type="box" size="0.03 0.002 0.002" pos="0 0 -0.012" rgba="0 0 1 1" contype="0" conaffinity="0"/>
    </body>
        
    
    <body name="grasping_head_88" pos="19 91 91">
      <geom name="center_88" type="cylinder" size="0.003 0.015" pos="0.0 0.0 -0.028" rgba="0 0 1 1" contype="0" conaffinity="0"/>
      <geom name="cylinder_left_88" type="cylinder" size="0.003 0.02" pos="0.032 0 0.006" rgba="0 0 1 1" contype="0" conaffinity="0"/>
      <geom name="cylinder_right_88" type="cylinder" size="0.003 0.02" pos="-0.032 0 0.006" rgba="0 0 1 1" contype="0" conaffinity="0"/>
      <geom name="connecting_bar_88" type="box" size="0.03 0.002 0.002" pos="0 0 -0.012" rgba="0 0 1 1" contype="0" conaffinity="0"/>
    </body>
        
    
    <body name="grasping_head_89" pos="19 91 91">
      <geom name="center_89" type="cylinder" size="0.003 0.015" pos="0.0 0.0 -0.028" rgba="0 0 1 1" contype="0" conaffinity="0"/>
      <geom name="cylinder_left_89" type="cylinder" size="0.003 0.02" pos="0.032 0 0.006" rgba="0 0 1 1" contype="0" conaffinity="0"/>
      <geom name="cylinder_right_89" type="cylinder" size="0.003 0.02" pos="-0.032 0 0.006" rgba="0 0 1 1" contype="0" conaffinity="0"/>
      <geom name="connecting_bar_89" type="box" size="0.03 0.002 0.002" pos="0 0 -0.012" rgba="0 0 1 1" contype="0" conaffinity="0"/>
    </body>
        
    
    <body name="grasping_head_90" pos="19 91 91">
      <geom name="center_90" type="cylinder" size="0.003 0.015" pos="0.0 0.0 -0.028" rgba="0 0 1 1" contype="0" conaffinity="0"/>
      <geom name="cylinder_left_90" type="cylinder" size="0.003 0.02" pos="0.032 0 0.006" rgba="0 0 1 1" contype="0" conaffinity="0"/>
      <geom name="cylinder_right_90" type="cylinder" size="0.003 0.02" pos="-0.032 0 0.006" rgba="0 0 1 1" contype="0" conaffinity="0"/>
      <geom name="connecting_bar_90" type="box" size="0.03 0.002 0.002" pos="0 0 -0.012" rgba="0 0 1 1" contype="0" conaffinity="0"/>
    </body>
        
    
    <body name="grasping_head_91" pos="19 91 91">
      <geom name="center_91" type="cylinder" size="0.003 0.015" pos="0.0 0.0 -0.028" rgba="0 0 1 1" contype="0" conaffinity="0"/>
      <geom name="cylinder_left_91" type="cylinder" size="0.003 0.02" pos="0.032 0 0.006" rgba="0 0 1 1" contype="0" conaffinity="0"/>
      <geom name="cylinder_right_91" type="cylinder" size="0.003 0.02" pos="-0.032 0 0.006" rgba="0 0 1 1" contype="0" conaffinity="0"/>
      <geom name="connecting_bar_91" type="box" size="0.03 0.002 0.002" pos="0 0 -0.012" rgba="0 0 1 1" contype="0" conaffinity="0"/>
    </body>
        
    
    <body name="grasping_head_92" pos="19 91 91">
      <geom name="center_92" type="cylinder" size="0.003 0.015" pos="0.0 0.0 -0.028" rgba="0 0 1 1" contype="0" conaffinity="0"/>
      <geom name="cylinder_left_92" type="cylinder" size="0.003 0.02" pos="0.032 0 0.006" rgba="0 0 1 1" contype="0" conaffinity="0"/>
      <geom name="cylinder_right_92" type="cylinder" size="0.003 0.02" pos="-0.032 0 0.006" rgba="0 0 1 1" contype="0" conaffinity="0"/>
      <geom name="connecting_bar_92" type="box" size="0.03 0.002 0.002" pos="0 0 -0.012" rgba="0 0 1 1" contype="0" conaffinity="0"/>
    </body>
        
    
    <body name="grasping_head_93" pos="19 91 91">
      <geom name="center_93" type="cylinder" size="0.003 0.015" pos="0.0 0.0 -0.028" rgba="0 0 1 1" contype="0" conaffinity="0"/>
      <geom name="cylinder_left_93" type="cylinder" size="0.003 0.02" pos="0.032 0 0.006" rgba="0 0 1 1" contype="0" conaffinity="0"/>
      <geom name="cylinder_right_93" type="cylinder" size="0.003 0.02" pos="-0.032 0 0.006" rgba="0 0 1 1" contype="0" conaffinity="0"/>
      <geom name="connecting_bar_93" type="box" size="0.03 0.002 0.002" pos="0 0 -0.012" rgba="0 0 1 1" contype="0" conaffinity="0"/>
    </body>
        
    
    <body name="grasping_head_94" pos="19 91 91">
      <geom name="center_94" type="cylinder" size="0.003 0.015" pos="0.0 0.0 -0.028" rgba="0 0 1 1" contype="0" conaffinity="0"/>
      <geom name="cylinder_left_94" type="cylinder" size="0.003 0.02" pos="0.032 0 0.006" rgba="0 0 1 1" contype="0" conaffinity="0"/>
      <geom name="cylinder_right_94" type="cylinder" size="0.003 0.02" pos="-0.032 0 0.006" rgba="0 0 1 1" contype="0" conaffinity="0"/>
      <geom name="connecting_bar_94" type="box" size="0.03 0.002 0.002" pos="0 0 -0.012" rgba="0 0 1 1" contype="0" conaffinity="0"/>
    </body>
        
    
    <body name="grasping_head_95" pos="19 91 91">
      <geom name="center_95" type="cylinder" size="0.003 0.015" pos="0.0 0.0 -0.028" rgba="0 0 1 1" contype="0" conaffinity="0"/>
      <geom name="cylinder_left_95" type="cylinder" size="0.003 0.02" pos="0.032 0 0.006" rgba="0 0 1 1" contype="0" conaffinity="0"/>
      <geom name="cylinder_right_95" type="cylinder" size="0.003 0.02" pos="-0.032 0 0.006" rgba="0 0 1 1" contype="0" conaffinity="0"/>
      <geom name="connecting_bar_95" type="box" size="0.03 0.002 0.002" pos="0 0 -0.012" rgba="0 0 1 1" contype="0" conaffinity="0"/>
    </body>
        
    
    <body name="grasping_head_96" pos="19 91 91">
      <geom name="center_96" type="cylinder" size="0.003 0.015" pos="0.0 0.0 -0.028" rgba="0 0 1 1" contype="0" conaffinity="0"/>
      <geom name="cylinder_left_96" type="cylinder" size="0.003 0.02" pos="0.032 0 0.006" rgba="0 0 1 1" contype="0" conaffinity="0"/>
      <geom name="cylinder_right_96" type="cylinder" size="0.003 0.02" pos="-0.032 0 0.006" rgba="0 0 1 1" contype="0" conaffinity="0"/>
      <geom name="connecting_bar_96" type="box" size="0.03 0.002 0.002" pos="0 0 -0.012" rgba="0 0 1 1" contype="0" conaffinity="0"/>
    </body>
        
    
    <body name="grasping_head_97" pos="19 91 91">
      <geom name="center_97" type="cylinder" size="0.003 0.015" pos="0.0 0.0 -0.028" rgba="0 0 1 1" contype="0" conaffinity="0"/>
      <geom name="cylinder_left_97" type="cylinder" size="0.003 0.02" pos="0.032 0 0.006" rgba="0 0 1 1" contype="0" conaffinity="0"/>
      <geom name="cylinder_right_97" type="cylinder" size="0.003 0.02" pos="-0.032 0 0.006" rgba="0 0 1 1" contype="0" conaffinity="0"/>
      <geom name="connecting_bar_97" type="box" size="0.03 0.002 0.002" pos="0 0 -0.012" rgba="0 0 1 1" contype="0" conaffinity="0"/>
    </body>
        
    
    <body name="grasping_head_98" pos="19 91 91">
      <geom name="center_98" type="cylinder" size="0.003 0.015" pos="0.0 0.0 -0.028" rgba="0 0 1 1" contype="0" conaffinity="0"/>
      <geom name="cylinder_left_98" type="cylinder" size="0.003 0.02" pos="0.032 0 0.006" rgba="0 0 1 1" contype="0" conaffinity="0"/>
      <geom name="cylinder_right_98" type="cylinder" size="0.003 0.02" pos="-0.032 0 0.006" rgba="0 0 1 1" contype="0" conaffinity="0"/>
      <geom name="connecting_bar_98" type="box" size="0.03 0.002 0.002" pos="0 0 -0.012" rgba="0 0 1 1" contype="0" conaffinity="0"/>
    </body>
        
    
    <body name="grasping_head_99" pos="19 91 91">
      <geom name="center_99" type="cylinder" size="0.003 0.015" pos="0.0 0.0 -0.028" rgba="0 0 1 1" contype="0" conaffinity="0"/>
      <geom name="cylinder_left_99" type="cylinder" size="0.003 0.02" pos="0.032 0 0.006" rgba="0 0 1 1" contype="0" conaffinity="0"/>
      <geom name="cylinder_right_99" type="cylinder" size="0.003 0.02" pos="-0.032 0 0.006" rgba="0 0 1 1" contype="0" conaffinity="0"/>
      <geom name="connecting_bar_99" type="box" size="0.03 0.002 0.002" pos="0 0 -0.012" rgba="0 0 1 1" contype="0" conaffinity="0"/>
    </body>
        
    <body name="grasping_head" pos="1 1 1">
      <geom name="ceter" type="cylinder" size="0.003 0.015" pos="0.0 0.0 -0.028" rgba="1 0 0 1" contype="0" conaffinity="0"/>
      <geom name="cylinder_left" type="cylinder" size="0.003 0.02" pos="0.032 0 0.006" rgba="1 0 0 1" contype="0" conaffinity="0"/>
      <geom name="cylinder_right" type="cylinder" size="0.003 0.02" pos="-0.032 0 0.006" rgba="1 0 0 1" contype="0" conaffinity="0"/>
      <geom name="connecting_bar" type="box" size="0.03 0.002 0.002" pos="0 0 -0.012" rgba="1 0 0 1" contype="0" conaffinity="0"/>
    </body>



<!-- Handles -->
<body name="handle_1" pos="19 91 91">
  <geom name="handle_1_geom" type="sphere" size="0.05" pos="0.0 0.0 0.0" rgba="1 0 0 1" contype="0" conaffinity="0"/>
</body>

<body name="handle_2" pos="19 91 91">
  <geom name="handle_2_geom" type="sphere" size="0.05" pos="0.0 0.0 0.0" rgba="1 0 0 1" contype="0" conaffinity="0"/>
</body>

<body name="handle_3" pos="19 91 91">
  <geom name="handle_3_geom" type="sphere" size="0.05" pos="0.0 0.0 0.0" rgba="1 0 0 1" contype="0" conaffinity="0"/>
</body>

<body name="handle_4" pos="19 91 91">
  <geom name="handle_4_geom" type="sphere" size="0.05" pos="0.0 0.0 0.0" rgba="1 0 0 1" contype="0" conaffinity="0"/>
</body>

<body name="handle_5" pos="19 91 91">
  <geom name="handle_5_geom" type="sphere" size="0.05" pos="0.0 0.0 0.0" rgba="1 0 0 1" contype="0" conaffinity="0"/>
</body>

<body name="handle_6" pos="19 91 91">
  <geom name="handle_6_geom" type="sphere" size="0.05" pos="0.0 0.0 0.0" rgba="1 0 0 1" contype="0" conaffinity="0"/>
</body>

<body name="handle_7" pos="19 91 91">
  <geom name="handle_7_geom" type="sphere" size="0.05" pos="0.0 0.0 0.0" rgba="1 0 0 1" contype="0" conaffinity="0"/>
</body>

<body name="handle_8" pos="19 91 91">
  <geom name="handle_8_geom" type="sphere" size="0.05" pos="0.0 0.0 0.0" rgba="1 0 0 1" contype="0" conaffinity="0"/>
</body>

<body name="handle_9" pos="19 91 91">
  <geom name="handle_9_geom" type="sphere" size="0.05" pos="0.0 0.0 0.0" rgba="1 0 0 1" contype="0" conaffinity="0"/>
</body>

<body name="handle_10" pos="19 91 91">
  <geom name="handle_10_geom" type="sphere" size="0.05" pos="0.0 0.0 0.0" rgba="1 0 0 1" contype="0" conaffinity="0"/>
</body>

<body name="handle_11" pos="19 91 91">
  <geom name="handle_11_geom" type="sphere" size="0.05" pos="0.0 0.0 0.0" rgba="1 0 0 1" contype="0" conaffinity="0"/>
</body>

<body name="handle_12" pos="19 91 91">
  <geom name="handle_12_geom" type="sphere" size="0.05" pos="0.0 0.0 0.0" rgba="1 0 0 1" contype="0" conaffinity="0"/>
</body>

<body name="handle_13" pos="19 91 91">
  <geom name="handle_13_geom" type="sphere" size="0.05" pos="0.0 0.0 0.0" rgba="1 0 0 1" contype="0" conaffinity="0"/>
</body>

<body name="handle_14" pos="19 91 91">
  <geom name="handle_14_geom" type="sphere" size="0.05" pos="0.0 0.0 0.0" rgba="1 0 0 1" contype="0" conaffinity="0"/>
</body>

<body name="handle_15" pos="19 91 91">
  <geom name="handle_15_geom" type="sphere" size="0.05" pos="0.0 0.0 0.0" rgba="1 0 0 1" contype="0" conaffinity="0"/>
</body>

<body name="handle_16" pos="19 91 91">
  <geom name="handle_16_geom" type="sphere" size="0.05" pos="0.0 0.0 0.0" rgba="1 0 0 1" contype="0" conaffinity="0"/>
</body>

<body name="handle_17" pos="19 91 91">
  <geom name="handle_17_geom" type="sphere" size="0.05" pos="0.0 0.0 0.0" rgba="1 0 0 1" contype="0" conaffinity="0"/>
</body>

<body name="handle_18" pos="19 91 91">
  <geom name="handle_18_geom" type="sphere" size="0.05" pos="0.0 0.0 0.0" rgba="1 0 0 1" contype="0" conaffinity="0"/>
</body>

<body name="handle_19" pos="19 91 91">
  <geom name="handle_19_geom" type="sphere" size="0.05" pos="0.0 0.0 0.0" rgba="1 0 0 1" contype="0" conaffinity="0"/>
</body>

<body name="handle_20" pos="19 91 91">
  <geom name="handle_20_geom" type="sphere" size="0.05" pos="0.0 0.0 0.0" rgba="1 0 0 1" contype="0" conaffinity="0"/>
</body>

<body name="handle_21" pos="19 91 91">
  <geom name="handle_21_geom" type="sphere" size="0.05" pos="0.0 0.0 0.0" rgba="1 0 0 1" contype="0" conaffinity="0"/>
</body>

<body name="handle_22" pos="19 91 91">
  <geom name="handle_22_geom" type="sphere" size="0.05" pos="0.0 0.0 0.0" rgba="1 0 0 1" contype="0" conaffinity="0"/>
</body>

<body name="handle_23" pos="19 91 91">
  <geom name="handle_23_geom" type="sphere" size="0.05" pos="0.0 0.0 0.0" rgba="1 0 0 1" contype="0" conaffinity="0"/>
</body>

<body name="handle_24" pos="19 91 91">
  <geom name="handle_24_geom" type="sphere" size="0.05" pos="0.0 0.0 0.0" rgba="1 0 0 1" contype="0" conaffinity="0"/>
</body>

<body name="handle_25" pos="19 91 91">
  <geom name="handle_25_geom" type="sphere" size="0.05" pos="0.0 0.0 0.0" rgba="1 0 0 1" contype="0" conaffinity="0"/>
</body>

<body name="handle_26" pos="19 91 91">
  <geom name="handle_26_geom" type="sphere" size="0.05" pos="0.0 0.0 0.0" rgba="1 0 0 1" contype="0" conaffinity="0"/>
</body>

<body name="handle_27" pos="19 91 91">
  <geom name="handle_27_geom" type="sphere" size="0.05" pos="0.0 0.0 0.0" rgba="1 0 0 1" contype="0" conaffinity="0"/>
</body>

<body name="handle_28" pos="19 91 91">
  <geom name="handle_28_geom" type="sphere" size="0.05" pos="0.0 0.0 0.0" rgba="1 0 0 1" contype="0" conaffinity="0"/>
</body>

<body name="handle_29" pos="19 91 91">
  <geom name="handle_29_geom" type="sphere" size="0.05" pos="0.0 0.0 0.0" rgba="1 0 0 1" contype="0" conaffinity="0"/>
</body>

<body name="handle_30" pos="19 91 91">
  <geom name="handle_30_geom" type="sphere" size="0.05" pos="0.0 0.0 0.0" rgba="1 0 0 1" contype="0" conaffinity="0"/>
</body>

<body name="handle_31" pos="19 91 91">
  <geom name="handle_31_geom" type="sphere" size="0.05" pos="0.0 0.0 0.0" rgba="1 0 0 1" contype="0" conaffinity="0"/>
</body>

<body name="handle_32" pos="19 91 91">
  <geom name="handle_32_geom" type="sphere" size="0.05" pos="0.0 0.0 0.0" rgba="1 0 0 1" contype="0" conaffinity="0"/>
</body>

<body name="handle_33" pos="19 91 91">
  <geom name="handle_33_geom" type="sphere" size="0.05" pos="0.0 0.0 0.0" rgba="1 0 0 1" contype="0" conaffinity="0"/>
</body>

<body name="handle_34" pos="19 91 91">
  <geom name="handle_34_geom" type="sphere" size="0.05" pos="0.0 0.0 0.0" rgba="1 0 0 1" contype="0" conaffinity="0"/>
</body>

<body name="handle_35" pos="19 91 91">
  <geom name="handle_35_geom" type="sphere" size="0.05" pos="0.0 0.0 0.0" rgba="1 0 0 1" contype="0" conaffinity="0"/>
</body>

<body name="handle_36" pos="19 91 91">
  <geom name="handle_36_geom" type="sphere" size="0.05" pos="0.0 0.0 0.0" rgba="1 0 0 1" contype="0" conaffinity="0"/>
</body>

<body name="handle_37" pos="19 91 91">
  <geom name="handle_37_geom" type="sphere" size="0.05" pos="0.0 0.0 0.0" rgba="1 0 0 1" contype="0" conaffinity="0"/>
</body>

<body name="handle_38" pos="19 91 91">
  <geom name="handle_38_geom" type="sphere" size="0.05" pos="0.0 0.0 0.0" rgba="1 0 0 1" contype="0" conaffinity="0"/>
</body>

<body name="handle_39" pos="19 91 91">
  <geom name="handle_39_geom" type="sphere" size="0.05" pos="0.0 0.0 0.0" rgba="1 0 0 1" contype="0" conaffinity="0"/>
</body>

<body name="handle_40" pos="19 91 91">
  <geom name="handle_40_geom" type="sphere" size="0.05" pos="0.0 0.0 0.0" rgba="1 0 0 1" contype="0" conaffinity="0"/>
</body>

<body name="handle_41" pos="19 91 91">
  <geom name="handle_41_geom" type="sphere" size="0.05" pos="0.0 0.0 0.0" rgba="1 0 0 1" contype="0" conaffinity="0"/>
</body>

<body name="handle_42" pos="19 91 91">
  <geom name="handle_42_geom" type="sphere" size="0.05" pos="0.0 0.0 0.0" rgba="1 0 0 1" contype="0" conaffinity="0"/>
</body>

<body name="handle_43" pos="19 91 91">
  <geom name="handle_43_geom" type="sphere" size="0.05" pos="0.0 0.0 0.0" rgba="1 0 0 1" contype="0" conaffinity="0"/>
</body>

<body name="handle_44" pos="19 91 91">
  <geom name="handle_44_geom" type="sphere" size="0.05" pos="0.0 0.0 0.0" rgba="1 0 0 1" contype="0" conaffinity="0"/>
</body>

<body name="handle_45" pos="19 91 91">
  <geom name="handle_45_geom" type="sphere" size="0.05" pos="0.0 0.0 0.0" rgba="1 0 0 1" contype="0" conaffinity="0"/>
</body>

<body name="handle_46" pos="19 91 91">
  <geom name="handle_46_geom" type="sphere" size="0.05" pos="0.0 0.0 0.0" rgba="1 0 0 1" contype="0" conaffinity="0"/>
</body>

<body name="handle_47" pos="19 91 91">
  <geom name="handle_47_geom" type="sphere" size="0.05" pos="0.0 0.0 0.0" rgba="1 0 0 1" contype="0" conaffinity="0"/>
</body>

<body name="handle_48" pos="19 91 91">
  <geom name="handle_48_geom" type="sphere" size="0.05" pos="0.0 0.0 0.0" rgba="1 0 0 1" contype="0" conaffinity="0"/>
</body>

<body name="handle_49" pos="19 91 91">
  <geom name="handle_49_geom" type="sphere" size="0.05" pos="0.0 0.0 0.0" rgba="1 0 0 1" contype="0" conaffinity="0"/>
</body>

<body name="handle_50" pos="19 91 91">
  <geom name="handle_50_geom" type="sphere" size="0.05" pos="0.0 0.0 0.0" rgba="1 0 0 1" contype="0" conaffinity="0"/>
</body>

<!-- Objects -->
<body name="object_1" pos="19 91 91">
  <geom name="object_1_geom" type="sphere" size="0.1" pos="0.0 0.0 0.0" rgba="0 0 1 1" contype="0" conaffinity="0"/>
</body>

<body name="object_2" pos="19 91 91">
  <geom name="object_2_geom" type="sphere" size="0.1" pos="0.0 0.0 0.0" rgba="0 0 1 1" contype="0" conaffinity="0"/>
</body>

<body name="object_3" pos="19 91 91">
  <geom name="object_3_geom" type="sphere" size="0.1" pos="0.0 0.0 0.0" rgba="0 0 1 1" contype="0" conaffinity="0"/>
</body>

<body name="object_4" pos="19 91 91">
  <geom name="object_4_geom" type="sphere" size="0.1" pos="0.0 0.0 0.0" rgba="0 0 1 1" contype="0" conaffinity="0"/>
</body>

<body name="object_5" pos="19 91 91">
  <geom name="object_5_geom" type="sphere" size="0.1" pos="0.0 0.0 0.0" rgba="0 0 1 1" contype="0" conaffinity="0"/>
</body>

<body name="object_6" pos="19 91 91">
  <geom name="object_6_geom" type="sphere" size="0.1" pos="0.0 0.0 0.0" rgba="0 0 1 1" contype="0" conaffinity="0"/>
</body>

<body name="object_7" pos="19 91 91">
  <geom name="object_7_geom" type="sphere" size="0.1" pos="0.0 0.0 0.0" rgba="0 0 1 1" contype="0" conaffinity="0"/>
</body>

<body name="object_8" pos="19 91 91">
  <geom name="object_8_geom" type="sphere" size="0.1" pos="0.0 0.0 0.0" rgba="0 0 1 1" contype="0" conaffinity="0"/>
</body>

<body name="object_9" pos="19 91 91">
  <geom name="object_9_geom" type="sphere" size="0.1" pos="0.0 0.0 0.0" rgba="0 0 1 1" contype="0" conaffinity="0"/>
</body>

<body name="object_10" pos="19 91 91">
  <geom name="object_10_geom" type="sphere" size="0.1" pos="0.0 0.0 0.0" rgba="0 0 1 1" contype="0" conaffinity="0"/>
</body>

<body name="object_11" pos="19 91 91">
  <geom name="object_11_geom" type="sphere" size="0.1" pos="0.0 0.0 0.0" rgba="0 0 1 1" contype="0" conaffinity="0"/>
</body>

<body name="object_12" pos="19 91 91">
  <geom name="object_12_geom" type="sphere" size="0.1" pos="0.0 0.0 0.0" rgba="0 0 1 1" contype="0" conaffinity="0"/>
</body>

<body name="object_13" pos="19 91 91">
  <geom name="object_13_geom" type="sphere" size="0.1" pos="0.0 0.0 0.0" rgba="0 0 1 1" contype="0" conaffinity="0"/>
</body>

<body name="object_14" pos="19 91 91">
  <geom name="object_14_geom" type="sphere" size="0.1" pos="0.0 0.0 0.0" rgba="0 0 1 1" contype="0" conaffinity="0"/>
</body>

<body name="object_15" pos="19 91 91">
  <geom name="object_15_geom" type="sphere" size="0.1" pos="0.0 0.0 0.0" rgba="0 0 1 1" contype="0" conaffinity="0"/>
</body>

<body name="object_16" pos="19 91 91">
  <geom name="object_16_geom" type="sphere" size="0.1" pos="0.0 0.0 0.0" rgba="0 0 1 1" contype="0" conaffinity="0"/>
</body>

<body name="object_17" pos="19 91 91">
  <geom name="object_17_geom" type="sphere" size="0.1" pos="0.0 0.0 0.0" rgba="0 0 1 1" contype="0" conaffinity="0"/>
</body>

<body name="object_18" pos="19 91 91">
  <geom name="object_18_geom" type="sphere" size="0.1" pos="0.0 0.0 0.0" rgba="0 0 1 1" contype="0" conaffinity="0"/>
</body>

<body name="object_19" pos="19 91 91">
  <geom name="object_19_geom" type="sphere" size="0.1" pos="0.0 0.0 0.0" rgba="0 0 1 1" contype="0" conaffinity="0"/>
</body>

<body name="object_20" pos="19 91 91">
  <geom name="object_20_geom" type="sphere" size="0.1" pos="0.0 0.0 0.0" rgba="0 0 1 1" contype="0" conaffinity="0"/>
</body>

<body name="object_21" pos="19 91 91">
  <geom name="object_21_geom" type="sphere" size="0.1" pos="0.0 0.0 0.0" rgba="0 0 1 1" contype="0" conaffinity="0"/>
</body>

<body name="object_22" pos="19 91 91">
  <geom name="object_22_geom" type="sphere" size="0.1" pos="0.0 0.0 0.0" rgba="0 0 1 1" contype="0" conaffinity="0"/>
</body>

<body name="object_23" pos="19 91 91">
  <geom name="object_23_geom" type="sphere" size="0.1" pos="0.0 0.0 0.0" rgba="0 0 1 1" contype="0" conaffinity="0"/>
</body>

<body name="object_24" pos="19 91 91">
  <geom name="object_24_geom" type="sphere" size="0.1" pos="0.0 0.0 0.0" rgba="0 0 1 1" contype="0" conaffinity="0"/>
</body>

<body name="object_25" pos="19 91 91">
  <geom name="object_25_geom" type="sphere" size="0.1" pos="0.0 0.0 0.0" rgba="0 0 1 1" contype="0" conaffinity="0"/>
</body>

<body name="object_26" pos="19 91 91">
  <geom name="object_26_geom" type="sphere" size="0.1" pos="0.0 0.0 0.0" rgba="0 0 1 1" contype="0" conaffinity="0"/>
</body>

<body name="object_27" pos="19 91 91">
  <geom name="object_27_geom" type="sphere" size="0.1" pos="0.0 0.0 0.0" rgba="0 0 1 1" contype="0" conaffinity="0"/>
</body>

<body name="object_28" pos="19 91 91">
  <geom name="object_28_geom" type="sphere" size="0.1" pos="0.0 0.0 0.0" rgba="0 0 1 1" contype="0" conaffinity="0"/>
</body>

<body name="object_29" pos="19 91 91">
  <geom name="object_29_geom" type="sphere" size="0.1" pos="0.0 0.0 0.0" rgba="0 0 1 1" contype="0" conaffinity="0"/>
</body>

<body name="object_30" pos="19 91 91">
  <geom name="object_30_geom" type="sphere" size="0.1" pos="0.0 0.0 0.0" rgba="0 0 1 1" contype="0" conaffinity="0"/>
</body>

<body name="object_31" pos="19 91 91">
  <geom name="object_31_geom" type="sphere" size="0.1" pos="0.0 0.0 0.0" rgba="0 0 1 1" contype="0" conaffinity="0"/>
</body>

<body name="object_32" pos="19 91 91">
  <geom name="object_32_geom" type="sphere" size="0.1" pos="0.0 0.0 0.0" rgba="0 0 1 1" contype="0" conaffinity="0"/>
</body>

<body name="object_33" pos="19 91 91">
  <geom name="object_33_geom" type="sphere" size="0.1" pos="0.0 0.0 0.0" rgba="0 0 1 1" contype="0" conaffinity="0"/>
</body>

<body name="object_34" pos="19 91 91">
  <geom name="object_34_geom" type="sphere" size="0.1" pos="0.0 0.0 0.0" rgba="0 0 1 1" contype="0" conaffinity="0"/>
</body>

<body name="object_35" pos="19 91 91">
  <geom name="object_35_geom" type="sphere" size="0.1" pos="0.0 0.0 0.0" rgba="0 0 1 1" contype="0" conaffinity="0"/>
</body>

<body name="object_36" pos="19 91 91">
  <geom name="object_36_geom" type="sphere" size="0.1" pos="0.0 0.0 0.0" rgba="0 0 1 1" contype="0" conaffinity="0"/>
</body>

<body name="object_37" pos="19 91 91">
  <geom name="object_37_geom" type="sphere" size="0.1" pos="0.0 0.0 0.0" rgba="0 0 1 1" contype="0" conaffinity="0"/>
</body>

<body name="object_38" pos="19 91 91">
  <geom name="object_38_geom" type="sphere" size="0.1" pos="0.0 0.0 0.0" rgba="0 0 1 1" contype="0" conaffinity="0"/>
</body>

<body name="object_39" pos="19 91 91">
  <geom name="object_39_geom" type="sphere" size="0.1" pos="0.0 0.0 0.0" rgba="0 0 1 1" contype="0" conaffinity="0"/>
</body>

<body name="object_40" pos="19 91 91">
  <geom name="object_40_geom" type="sphere" size="0.1" pos="0.0 0.0 0.0" rgba="0 0 1 1" contype="0" conaffinity="0"/>
</body>

<body name="object_41" pos="19 91 91">
  <geom name="object_41_geom" type="sphere" size="0.1" pos="0.0 0.0 0.0" rgba="0 0 1 1" contype="0" conaffinity="0"/>
</body>

<body name="object_42" pos="19 91 91">
  <geom name="object_42_geom" type="sphere" size="0.1" pos="0.0 0.0 0.0" rgba="0 0 1 1" contype="0" conaffinity="0"/>
</body>

<body name="object_43" pos="19 91 91">
  <geom name="object_43_geom" type="sphere" size="0.1" pos="0.0 0.0 0.0" rgba="0 0 1 1" contype="0" conaffinity="0"/>
</body>

<body name="object_44" pos="19 91 91">
  <geom name="object_44_geom" type="sphere" size="0.1" pos="0.0 0.0 0.0" rgba="0 0 1 1" contype="0" conaffinity="0"/>
</body>

<body name="object_45" pos="19 91 91">
  <geom name="object_45_geom" type="sphere" size="0.1" pos="0.0 0.0 0.0" rgba="0 0 1 1" contype="0" conaffinity="0"/>
</body>

<body name="object_46" pos="19 91 91">
  <geom name="object_46_geom" type="sphere" size="0.1" pos="0.0 0.0 0.0" rgba="0 0 1 1" contype="0" conaffinity="0"/>
</body>

<body name="object_47" pos="19 91 91">
  <geom name="object_47_geom" type="sphere" size="0.1" pos="0.0 0.0 0.0" rgba="0 0 1 1" contype="0" conaffinity="0"/>
</body>

<body name="object_48" pos="19 91 91">
  <geom name="object_48_geom" type="sphere" size="0.1" pos="0.0 0.0 0.0" rgba="0 0 1 1" contype="0" conaffinity="0"/>
</body>

<body name="object_49" pos="19 91 91">
  <geom name="object_49_geom" type="sphere" size="0.1" pos="0.0 0.0 0.0" rgba="0 0 1 1" contype="0" conaffinity="0"/>
</body>

<body name="object_50" pos="19 91 91">
  <geom name="object_50_geom" type="sphere" size="0.1" pos="0.0 0.0 0.0" rgba="0 0 1 1" contype="0" conaffinity="0"/>
</body>



<body name="eef_target" pos="1 1 1" quat="1 0 0 0">
  <!-- Left finger of the gripper -->
  <body name="left_finger" pos="0 0.0 0.015">
    <geom name="left_eef_link" type="box" size="0.003 0.02 0.003" pos="0 0 0" quat="1 0 0 0" rgba="0 0 1 0.5" />
  </body>
  
  <!-- Right finger of the gripper -->
  <body name="right_finger" pos="0 0.0 -0.015">
    <geom name="right_eef_link" type="box" size="0.003 0.02 0.003" pos="0 0 0" quat="1 0 0 0" rgba="0 0 1 0.5" contype="0" conaffinity="0"/>
  </body>
  
  <!-- Connecting block of the gripper -->
  <body name="connector" pos="0 0.02 0">
    <geom name="connector_geom" type="box" size="0.003 0.003 0.02" pos="0 0 0" quat="1 0 0 0" rgba="0 0 1 0.5" contype="0" conaffinity="0"/>
  </body>




 


</body>

    <geom name="eef_center" type="sphere" size="0.035" pos="100 100 0.001" rgba="1 0 0 0.5"/>



    <body name="base_link" childclass="stretch">
      <freejoint/>
      <geom mesh="base_link_0" material="Caster_Rollers_Red" density="100" class="visual"/>
      <geom mesh="base_link_2" material="Lightbar_Green" density="100" class="visual" shellinertia="true"/>
      <geom mesh="base_link_3" material="Power_Button_Green" density="100" class="visual"/>
      <geom mesh="base_link_4" material="USB_Blue" density="100" class="visual"/>
      <geom mesh="base_link_5" material="Generic_Black" density="100" class="visual"/>
      <geom mesh="base_link_6" material="Hand_Crush_Sticker" density="100" class="visual" shellinertia="true"/>
      <geom mesh="base_link_7" material="Pantone_705_U" density="100" class="visual"/>
      <geom mesh="base_link_8" material="Pantone_Cool_Gray_4_U" density="100" class="visual"/>
      <geom class="collision" mesh="base_link_collision" mass="25.0"/>
      <geom class="caster"/>
      <body name="base_imu" pos="-0.12838 0.0031592 0.1474" euler="-3.1416 0 1.5708">
        <site name="base_imu" pos="0 0 0"/>
      </body>
        
      <body name="link_mast" pos="-0.067 0.135 0.0284" quat="1 1 0 0">
        <geom material="Generic_Black" mesh="link_mast" class="visual"/>
        <geom mesh="link_mast" class="collision" mass="1.8285"/>
      </body>
      <body name="link_head" pos="-0.067 0.134995 1.3584" quat="-1 0 0 1">
        <geom mesh="link_head_0" material="Runstop_White_Glow" class="visual"/>
        <geom mesh="link_head_1" material="Generic_Black" class="visual"/>
        <geom mesh="link_head_2" material="Speaker_Housing_Black" class="visual"/>
        <geom mesh="link_head_3" material="Reflective_Metal" class="visual"/>
        <geom mesh="link_head_4" material="Reflective_Metal" class="visual"/>
        <geom mesh="link_head_5" material="Pure_Black" class="visual"/>
        <geom mesh="link_head_6" material="Reflective_Metal" class="visual"/>
        <geom mesh="link_head_7" material="Plug_White" class="visual"/>
        <geom mesh="link_head_8" material="3D_Print_Black" class="visual"/>
        <geom mesh="link_head_9" material="Respeaker_Blue_Glow" class="visual"/>
        <geom mesh="link_head_10" material="Pantone_Black_6_U" class="visual"/>
        <geom mesh="link_head_11" material="Generic_Black" class="visual"/>
        <geom mesh="link_head_10" class="collision" mass="0.833027236718691"/>
      </body>
      <body name="link_aruco_right_base" pos="-0.0015028 -0.130497 0.159748" quat="1 0 0 -1">
        <geom material="Aruco_Right_Base_Sticker" mesh="link_aruco_right_base" class="visual" mass="3.6E-06"
          shellinertia="true"/>
        <geom mesh="link_aruco_right_base" class="collision"/>
      </body>
      <body name="link_aruco_left_base" pos="-0.0015028 0.130497 0.159748" quat="1 0 0 -1">
        <geom material="Aruco_Left_Base_Sticker" mesh="link_aruco_left_base" class="visual" mass="3.6E-06"
          shellinertia="true"/>
        <geom mesh="link_aruco_left_base" class="collision"/>
      </body>
      <body name="laser" pos="0.004 0 0.1664" quat="0 0 0 1">
        <geom material="Laser_Black" mesh="laser" class="visual" mass="0.24"/>
        <geom mesh="laser" class="collision"/>
      </body>
      <body name="link_right_wheel" pos="0 -0.17035 0.0508" quat="1 -1 0 0">
        <joint name="joint_right_wheel" class="wheel"/>
        <geom mesh="link_right_wheel_0" material="Wheel_Rubber_Gray" class="visual" mass="0.15"/>
        <geom mesh="link_right_wheel_1" material="Generic_Black" class="visual"/>
        <geom class="collision" type="cylinder" size=".05 .0125" pos="0 0 0.0125" condim="6"/>
      </body>
      <body name="link_left_wheel" pos="0 0.17035 0.0508" quat="1 -1 0 0">
        <joint name="joint_left_wheel" class="wheel"/>
        <geom mesh="link_left_wheel_0" material="Wheel_Rubber_Gray" class="visual" mass="0.15"/>
        <geom mesh="link_left_wheel_1" material="Generic_Black" class="visual"/>
        <geom class="collision" type="cylinder" size=".05 .0125" pos="0 0 -0.0125" condim="6"/>
      </body>
      <body name="link_lift" gravcomp="1" pos="-0.104385 0.134999 0.2" quat="1 0 0 1">
        <joint name="joint_lift" class="lift"/>
        <geom mesh="link_lift_0" material="Pantone_705_U" class="visual"/>
        <geom mesh="link_lift_2" material="Pure_Black" class="visual"/>
        <geom mesh="link_lift_3" material="Reflective_Metal" class="visual"/>
        <geom mesh="link_lift_4" material="Plug_White" class="visual"/>
        <geom mesh="link_lift_5" material="Pantone_Black_6_U" class="visual"/>
        <geom mesh="link_lift_6" material="Generic_Black" class="visual"/>
        <geom mesh="link_lift_7" material="Generic_Black" class="visual"/>
        <geom mesh="link_lift_8" material="3D_Print_Black" class="visual"/>
        <geom mesh="link_lift_9" material="Pantone_Black_6_U" class="visual"/>
        <geom mesh="link_lift_0" class="collision"/>
        <geom mesh="link_lift_2" class="collision"/>
        <geom mesh="link_lift_3" class="collision"/>
        <geom mesh="link_lift_4" class="collision"/>
        <geom mesh="link_lift_5" class="collision"/>
        <geom mesh="link_lift_6" class="collision"/>
        <geom mesh="link_lift_7" class="collision"/>
        <geom mesh="link_lift_8" class="collision" mass="1.5"/>
        <geom mesh="link_lift_9" class="collision" mass="1.5"/>
        <body name="link_arm_l4" gravcomp="1">
          <geom mesh="link_arm_l4_0" pos="-0.2547 0 0" quat="0.5 0.5 -0.5 -0.5" material="Carbon_Fiber" class="visual"/>
          <geom mesh="link_arm_l4_1" pos="-0.2547 0 0" quat="0.5 0.5 -0.5 -0.5" material="3D_Print_Black" class="visual"/>
          <geom mesh="link_arm_l4_0" pos="-0.2547 0 0" quat="0.5 0.5 -0.5 -0.5" class="collision" mass="0.168095"/>
          <geom mesh="link_arm_l4_1" pos="-0.2547 0 0" quat="0.5 0.5 -0.5 -0.5" class="collision"/>
          <body name="link_arm_l3" pos="-0.2677 0 0" quat="0.5 0.5 -0.5 -0.5" gravcomp="1">
            <joint name="joint_arm_l3" class="telescope"/>
            <geom mesh="link_arm_l3_0" material="Carbon_Fiber" class="visual" mass="0.162893"/>
            <geom mesh="link_arm_l3_1" material="3D_Print_Black" class="visual"/>
            <geom mesh="link_arm_l3_0" class="collision"/>
            <geom mesh="link_arm_l3_1" class="collision"/>
            <body name="link_arm_l2" pos="0 0 0.013" gravcomp="1">
              <joint name="joint_arm_l2" class="telescope"/>
              <geom mesh="link_arm_l2_0" material="Carbon_Fiber" class="visual" mass="0.157139"/>
              <geom mesh="link_arm_l2_1" material="3D_Print_Black" class="visual"/>
              <geom mesh="link_arm_l2_0" class="collision"/>
              <geom mesh="link_arm_l2_1" class="collision"/>
              <body name="link_arm_l1" pos="0 0 0.013" gravcomp="1">
                <joint name="joint_arm_l1" class="telescope"/>
                <geom mesh="link_arm_l1_0" material="Carbon_Fiber" class="visual" mass="0.151382"/>
                <geom mesh="link_arm_l1_1" material="3D_Print_Black" class="visual"/>
                <geom mesh="link_arm_l1_0" class="collision"/>
                <geom mesh="link_arm_l1_1" class="collision"/>
                <body name="link_arm_l0" pos="0 0 -0.01375" quat="1 0 0 0" gravcomp="1">
                  <joint name="joint_arm_l0" class="telescope"/>
                  <geom mesh="link_arm_l0_0" material="3D_Print_Black" class="visual"/>
                  <geom mesh="link_arm_l0_1" material="Carbon_Fiber" class="visual" mass="0.28501"/>
                  <geom mesh="link_arm_l0_2" material="Generic_Black" class="visual"/>
                  <geom mesh="link_arm_l0_0" class="collision"/>
                  <geom mesh="link_arm_l0_1" class="collision"/>
                  <geom mesh="link_arm_l0_2" class="collision"/>
                  <body name="link_aruco_top_wrist" pos="0.04725 0.029285 0" quat="0 0 1 1">
                    <geom material="Aruco_Top_Wrist_Sticker" mesh="link_aruco_top_wrist" class="visual" mass="3.6E-06"
                      shellinertia="true"/>
                    <geom mesh="link_aruco_top_wrist" class="collision"/>
                  </body>
                  <body name="link_aruco_inner_wrist" pos="0.04725 -0.0119 -0.02725" quat="0 0 1 0">
                    <geom material="Aruco_Inner_Wrist_Sticker" mesh="link_aruco_inner_wrist" class="visual"
                      mass="3.6E-06" shellinertia="true"/>
                    <geom mesh="link_aruco_inner_wrist" class="collision"/>
                  </body>
                  <!-- Dex Wrist 3 Tree -->
                  <body name="link_wrist_yaw" pos="0.083 -0.03075 0" quat="-1 -1 0 0" gravcomp="1">
                    <joint name="joint_wrist_yaw" class="wrist_yaw"/>
                    <geom material="Generic_Black" mesh="link_wrist_yaw" mass="0.1445" class="visual"/>
                    <geom mesh="link_wrist_yaw" class="collision"/>
                    <geom quat="0 1 1 0" pos="0 0 0" mesh="link_DW3_wrist_yaw_bottom" material="Generic_Black" class="visual"/>
                    <geom mesh="link_DW3_wrist_yaw_bottom" class="collision"/>
                      <body name="link_DW3_wrist_pitch" pos="-0.01946 0 0.0305" euler="0 1.57 -1.57" gravcomp="1">
                        <joint name="joint_wrist_pitch" axis="0 0 -1" class="wrist_pitch"/>
                        <geom material="Generic_Black" mesh="link_DW3_wrist_pitch" mass="0.1165" class="visual"/>
                        <geom mesh="link_DW3_wrist_pitch" class="collision"/>
                        <geom pos="-0.0265 -0.024 0.0196" quat="1 0 0 1" mesh="link_DW3_wrist_quick_connect" material="Generic_Black" class="visual"/>
                        <geom mesh="link_DW3_wrist_quick_connect" class="collision"/>
                        <body name="link_SG3_gripper_body" pos="-0.0399 -0.024 0.0196" quat="1 0 -1 0" gravcomp="1">
                          <joint name="joint_wrist_roll" class="wrist_roll"/>
                          <geom material="Generic_Black" mesh="link_SG3_gripper_body" mass="0.29" class="visual"/>
                          <geom mesh="link_SG3_gripper_body" class="collision"/>
                          <body name="link_SG3_aruco_d405" pos="0 0.0671264013906604 0.0297716109784749" euler="-1.397059993 3.139694278 -0.001741181" gravcomp="1"> 
                            <geom material="Aruco_gripper_cam_Sticker" mesh="link_SG3_aruco_d405" class="visual" mass="3.6E-06"
                            shellinertia="true"/>
                            <geom mesh="link_SG3_aruco_d405" class="collision"/>
                            <body name="link_d405" pos="0 -0.03068 0" euler="1.57 0 0"> 
                              <geom material="Reflective_Metal" mesh="link_d405" mass="0.29" class="visual"/>
                              <geom material="Gray_Lens" mesh="link_d405_lens" pos="0 0 0" euler="0 0 0" mass="3.6E-06" class="visual"/>
                              <geom material="Pantone_Black_6_U" mesh="link_d405_front_plate" pos="0 0 0" euler="0 0 0" mass="3.6E-06" class="visual"/>
                              <geom mesh="link_d405" class="collision"/>
                              <body name="d405_cam" pos="0 0 0" euler="0 0 3.14">
                                <camera name="d405_rgb" pos="0 0 0" euler="-3.14 0 -3.14" fovy="58"/>
                                <camera name="d405_depth" pos="0 0 0" euler="-3.14 0 -3.14"/>
                              </body>
                            </body>
                          </body>
                          <body name="link_grasp_center" pos="0 0 0.23" euler="-1.5707963267949 -1.5707963267948 0"> </body>
                          <!-- Gripper Mechanism -->
                            <body name="link_gripper_slider" euler="0 0 0" pos="0 0 0" gravcomp="1">
                              <joint name="joint_gripper_slide" class="finger_slide"/>
                              <geom type="box" size=".03 .005 .005" mass=".05" class="visual" rgba="0 0 0 0"/>

                              <body name="link_gripper_finger_left" pos="0.02292 0.0020217 0.035297" euler="0 -1.57 3.1416" gravcomp="1">
                                <joint name="joint_gripper_finger_left_open" class="finger_open" stiffness="10"/>
                                <geom mesh="link_SG3_gripper_left_finger_0"  euler="1.57 0 0" material="Generic_Black" mass="0.05" class="visual"/>
                                <geom mesh="link_SG3_gripper_left_finger_0"  euler="1.57 0 0" class="collision"/>
                                <geom mesh="link_SG3_gripper_left_finger_1"  euler="1.57 0 0" material="White_Plastic" class="visual"/>
                                <geom mesh="link_SG3_gripper_left_finger_1"  euler="1.57 0 0" class="collision"/>
                                <geom mesh="link_SG3_gripper_inner_finger" pos="-0.17777 0.0018452 -0.011272" euler="3.1416 0.28 0" material="Reflective_Metal" mass="0.05" class="visual"/>
                                <body name="rubber_tip_left" pos="-0.17777 0.0018452 -0.011272" euler="0 -0.2618 -0.010379">
                                  <joint name="rubber_left_x" type="hinge" axis="1 0 0" damping=".01" stiffness="10" springref="0"/>
                                  <joint name="rubber_left_y" type="hinge" axis="0 1 0" damping=".01" stiffness="10" springref="0"/>
                                  <geom class="visual" mesh="link_SG3_gripper_left_fingertip" mass="0.005" material="suction_rubber"/>
                                  <!-- <geom class="visual" type="box"  size="0.02 0.02 0.01" pos="0 0 0.01" mass="0.005" material="suction_rubber"/> -->
                                  <geom type="box"  size="0.02 0.02 0.01" pos="0 0 0.01" class="rubber"/>
                                </body>
                                <body name="link_SG3_gripper_left_finger_aruco" pos="-0.14425 0.0014877 -0.005189" euler="0.19199 0.95993 3.1312"> 
                                  <geom material="Aruco_left_finger_Sticker" mesh="link_SG3_gripper_left_finger_aruco" class="visual" mass="3.6E-06" shellinertia="true"/>
                                  <geom mesh="link_SG3_gripper_left_finger_aruco" class="collision"/>
                                </body>
                              </body>

                              <body name="link_gripper_finger_right" pos="-0.023281 0 0.035287" euler="-3.1416 -1.57 3.1416" gravcomp="1">
                                <joint name="joint_gripper_finger_right_open" class="finger_open" stiffness="10"/>
                                <geom mesh="link_SG3_gripper_right_finger_0" euler="1.57 0 0" material="Generic_Black" mass="0.05" class="visual"/>
                                <geom mesh="link_SG3_gripper_right_finger_0" euler="1.57 0 0" class="collision"/>
                                <geom mesh="link_SG3_gripper_right_finger_1" euler="1.57 0 0" material="White_Plastic" mass="0.05" class="visual"/>
                                <geom mesh="link_SG3_gripper_right_finger_1" euler="1.57 0 0" class="collision"/>
                                <geom mesh="link_SG3_gripper_inner_finger" pos="0.17778 0 0.011272" euler="3.1416 -2.8616 0" material="Reflective_Metal" mass="0.05" class="visual"/>
                                <body name="rubber_tip_right" pos="0.17778 0 0.011272" euler="-3.1416 0.2618 -3.1416" gravcomp="1">
                                  <joint name="rubber_right_x" type="hinge" axis="1 0 0" damping=".01" stiffness="10" springref="0"/>
                                  <joint name="rubber_right_y" type="hinge" axis="0 1 0" damping=".01" stiffness="10" springref="0"/>
                                  <geom class="visual" material="suction_rubber" mesh="link_SG3_gripper_right_fingertip" mass="0.005"/>
                                  <!-- <geom class="visual" type="box"  size="0.02 0.02 0.01" pos="0 0 0.01" mass="0.005" material="suction_rubber"/> -->
                                  <geom type="box"   size="0.02 0.02 0.01" pos="0 0 0.01" class="rubber"/>
                                </body>
                                <body name="link_SG3_gripper_right_finger_aruco" pos="0.14426 0 0.005189" euler="-2.9496 -0.95993 3.1416"> 
                                  <geom material="Aruco_right_finger_Sticker" mesh="link_SG3_gripper_right_finger_aruco" class="visual" mass="3.6E-06" shellinertia="true"/>
                                  <geom mesh="link_SG3_gripper_right_finger_aruco" class="collision"/>
                                </body>
                              </body>
                            </body>
                        </body>
                      </body>
                  </body>
                </body>
              </body>
            </body>
          </body>
        </body>
        <body name="link_aruco_shoulder" pos="-0.0133769 0.0558541 0.0865" quat="1 0 0 0">
          <geom material="Aruco_Shoulder_Sticker" mesh="link_aruco_shoulder" class="visual" mass="3.6E-06"
          shellinertia="true"/>
          <geom mesh="link_aruco_shoulder" class="collision"/>
        </body>
      </body>
      <body name="link_head_pan" pos="0.00610002 0 1.3552" quat="-1 0 0 0">
        <joint name="joint_head_pan" class="head_pan"/>
        <geom mesh="link_head_pan_0" material="3D_Print_Black" class="visual"/>
        <geom mesh="link_head_pan_1" material="Generic_Black" class="visual" mass="0.127376"/>
        <geom mesh="link_head_pan_0" class="collision"/>
        <geom mesh="link_head_pan_1" class="collision"/>
        <body name="link_head_tilt" pos="-0.0013 0.0277625 -0.0533108" quat="1 1 0 0">
          <joint name="joint_head_tilt" class="head_tilt"/>
          <geom mesh="link_head_tilt_0" material="Pantone_Cool_Gray_4_U" class="visual" mass="0.1311085"/>
          <geom mesh="link_head_tilt_1" material="3D_Print_Black" class="visual" mass="0.1311085"/>
          <geom mesh="link_head_tilt_0" class="collision"/>
          <geom mesh="link_head_tilt_1" class="collision"/>
          <body name="realsense" pos="0.0406 0.0053 0.0307" euler="0 0 0">
            <camera name="d435i_camera_rgb" pos="0 0.015 0" euler="1.57 -1.57 0" fovy="58"/>
            <camera name="d435i_camera_depth" euler="1.57 -1.57 0"/>
          </body>
          <body name="link_SE3_head_nav_cam" pos="0.04 -0.0412 -0.0246" euler="0 1.5707963 0">
            <joint name="joint_head_nav_cam" class="head_tilt" stiffness="10"/>
            <geom mesh="link_SE3_head_nav_cam" material="Generic_Black" class="visual" mass="0.028346169831483"/>
            <body name="head_nav_cam" pos="0 0 0">
              <camera name="nav_camera_rgb" pos="0 0 0" euler="-3.1415926 0 3.1415926" fovy="69"/>
            </body>
          </body>
        </body>
      </body>
    </body>
  </worldbody>

  <contact>
    <exclude body1="link_head_pan" body2="link_head"/>
    <exclude body1="link_left_wheel" body2="base_link"/>
    <exclude body1="link_right_wheel" body2="base_link"/>
    <exclude body1="link_lift" body2="link_mast"/>
    <exclude body1="link_lift" body2="link_head"/>
    <exclude body1="link_arm_l0" body2="link_arm_l4"/>
    <exclude body1="link_arm_l0" body2="link_arm_l1"/>
    <exclude body1="link_arm_l1" body2="link_arm_l4"/>
    <exclude body1="link_arm_l2" body2="link_arm_l4"/>
    <exclude body1="link_arm_l3" body2="link_arm_l4"/>
    <exclude body1="link_arm_l0" body2="link_arm_l2"/>
    <exclude body1="link_arm_l0" body2="link_arm_l3"/>
    <exclude body1="link_arm_l0" body2="link_lift"/>
    <exclude body1="link_arm_l1" body2="link_arm_l3"/>
    <exclude body1="link_arm_l1" body2="link_lift"/>
    <exclude body1="link_arm_l2" body2="link_lift"/>
    <exclude body1="link_wrist_yaw" body2="link_arm_l0"/>
    <exclude body1="link_wrist_yaw" body2="link_arm_l1"/>
    <exclude body1="link_wrist_yaw" body2="link_arm_l2"/>
    <exclude body1="link_wrist_yaw" body2="link_arm_l3"/>
    <exclude body1="link_wrist_yaw" body2="link_arm_l4"/>
    <exclude body1="link_gripper_finger_left" body2="link_DW3_wrist_pitch"/>
    <exclude body1="link_gripper_finger_right" body2="link_DW3_wrist_pitch"/>
    <exclude body1="link_gripper_finger_left" body2="link_wrist_yaw"/>
    <exclude body1="link_gripper_finger_right" body2="link_wrist_yaw"/>
    <exclude body1="link_gripper_finger_left" body2="link_SG3_gripper_body"/>
    <exclude body1="link_gripper_finger_right" body2="link_SG3_gripper_body"/>
    <exclude body1="rubber_tip_right" body2="rubber_tip_left"/>
  </contact>

  <tendon>
    <fixed name="extend">
      <joint joint="joint_arm_l0" coef="1"/>
      <joint joint="joint_arm_l1" coef="1"/>
      <joint joint="joint_arm_l2" coef="1"/>
      <joint joint="joint_arm_l3" coef="1"/>
    </fixed>
  </tendon>

  <equality>
    <joint joint1="joint_arm_l0" joint2="joint_arm_l1"/>
    <joint joint1="joint_arm_l1" joint2="joint_arm_l2"/>
    <joint joint1="joint_arm_l2" joint2="joint_arm_l3"/>
    <joint joint1="joint_gripper_finger_left_open" joint2="joint_gripper_slide" polycoef="0 10 0 0 0" solref="0.005 1"/>
    <joint joint1="joint_gripper_finger_right_open" joint2="joint_gripper_slide" polycoef="0 10 0 0 0" solref="0.005 1"/>
  </equality>

  <actuator>
    <velocity name="left_wheel_vel" joint="joint_left_wheel" class="wheel"/>
    <velocity name="right_wheel_vel" joint="joint_right_wheel" class="wheel"/>
    <position name="lift" joint="joint_lift" class="lift"/>
    <position name="arm" tendon="extend" class="telescope"/>
    <position name="wrist_yaw" joint="joint_wrist_yaw" class="wrist_yaw"/>
    <position name="wrist_pitch" joint="joint_wrist_pitch" class="wrist_pitch"/>
    <position name="wrist_roll" joint="joint_wrist_roll" class="wrist_roll"/>
    <position name="gripper" joint="joint_gripper_slide" class="finger_slide"/>
    <position name="head_pan" joint="joint_head_pan" class="head_pan"/>
    <position name="head_tilt" joint="joint_head_tilt" class="head_tilt"/>
  </actuator>

  <sensor>
    <gyro name="base_gyro" site="base_imu"/>
    <accelerometer name="base_accel" site="base_imu"/>
  </sensor>

  <keyframe>
    <key name="home" ctrl="0 0 0.6 0.1 0 0 0 0 0 0"/>
    <key name="stow" ctrl="0 0 0.23 0 3.14 -0.4 0 0 0 0"/>
  </keyframe>

</mujoco>
